Workbook

Sheet Hoja1
A2: actividad | B2: cant
A3: 12. Revisión de Conexión a Unidad Manejadora de Conductos del sistema de distribución de aire ( SI APLICA ) | B3: 2
A4: 5. Inspección de Totalizadores. Breaker’s. Contactores. Protecciones y Medidores que hacen parte de la unidad Manejadora. | B4: 2
A5: 9. Lubricación de Chumaceras | B5: 3
A6: Amperaje del equipo | B6: 7
A7: Presión en psi de alta | B7: 7
A8: verificar estado y limpieza de caja electrica de control (tarjetas. ventiladores. conexiones) | B8: 2
A9: (A) Análisis del aceite del compresor para determinar cambio | B9: 1
A10: (A) Inspección de elementos de indicación | B10: 1
A11: (A) Inspección de las placas con líquidos penetrantes (si aplica) | B11: 1
A12: (A) Inspección y corrección de fugas | B12: 1
A13: (A) Lavado de serpentines con desincrustante (si es necesario) | B13: 1
A14: (A) Lectura de temperaturas de entrada de agua helada (°C) | B14: 1
... A2057: Work Order (W/O) | B2057: 1

Sheet tabla_carrascal
A1: Codigo | B1: Nombre | C1: descr | D1: desencruste | E1: pdesencruste | F1: limpieza | G1: plimpieza | H1: ajuste | I1: pajuste | J1: alineacion | K1: palineacion | L1: lubricacion | M1: plubricacion | N1: anticorrosivo | O1: panticorrosivo | P1: tp_equipo | Q1: tiempo | R1: personas | S1: orden | T1: mobra | U1: insumos | V1: materiales | W1: id
A2: 1 | B2: BORNES MOTOR | C2: AJUSTE | D2: 1 | E2: 60 | F2: 1 | G2: 30 | H2: 1 | I2: 30 | J2: 1 | K2: 90 | L2: 1 | M2: 90 | N2: 1 | O2: 120 | P2: 1 | Q2: 0.5 | R2: 1 | S2: 1 | T2: 0 | U2: 0 | V2: 0 | W2: 1
A3: 2 | B3: BLOWER | C3: LIMPIEZA DEL BLOWER,AJUSTE TORNILLOS | D3: 0 | E3: 0 | F3: 1 | G3: 0 | H3: 1 | I3: 0 | J3: 0 | K3: 0 | L3: 0 | M3: 0 | N3: 0 | O3: 0 | P3: 1 | Q3: 3 | R3: 1 | S3: 2 | T3: 0 | U3: 0 | V3: 0 | W3: 2
A4: 3 | B4: CARACOL | C4: LIMPIEZA, AJUSTE | D4: 0 | E4: 0 | F4: 1 | G4: 0 | H4: 1 | I4: 0 | J4: 0 | K4: 0 | L4: 0 | M4: 0 | N4: 0 | O4: 0 | P4: 1 | Q4: 1 | R4: 1 | S4: 3 | T4: 0 | U4: 0 | V4: 0 | W4: 3
A5: 4 | B5: AISLAMIENTO MANEJADORA | C5: LIMPIEZA, | D5: 0 | E5: 0 | F5: 1 | G5: 0 | H5: 0 | I5: 0 | J5: 0 | K5: 0 | L5: 0 | M5: 0 | N5: 0 | O5: 0 | P5: 1 | Q5: 0.5 | R5: 1 | S5: 4 | T5: 0 | U5: 0 | V5: 0 | W5: 4
A6: 5 | B6: CORREAS | C6: AJUSTE, INSPECION Y ALINEACION | D6: 0 | E6: 0 | F6: 0 | G6: 0 | H6: 1 | I6: 0 | J6: 0 | K6: 0 | L6: 0 | M6: 0 | N6: 0 | O6: 0 | P6: 1 | Q6: 0.5 | R6: 1 | S6: 5 | T6: 0 | U6: 0 | V6: 0 | W6: 5
A7: 6 | B7: AISLAMIENTO TUBERIA | C7: LIMPEZA, Y VERIFICACION DE SU ESTADO | D7: 0 | E7: 0 | F7: 1 | G7: 0 | H7: 0 | I7: 0 | J7: 0 | K7: 0 | L7: 0 | M7: 0 | N7: 0 | O7: 0 | P7: 1 | Q7: 1 | R7: 1 | S7: 6 | T7: 0 | U7: 0 | V7: 0 | W7: 6
A8: 7 | B8: POLEAS | C8: AJUSTE, Y ALINEACION | D8: 0 | E8: 0 | F8: 0 | G8: 0 | H8: 1 | I8: 0 | J8: 0 | K8: 0 | L8: 0 | M8: 0 | N8: 0 | O8: 0 | P8: 1 | Q8: 0.5 | R8: 1 | S8: 7 | T8: 0 | U8: 0 | V8: 0 | W8: 7
A9: 8 | B9: CABLEADO | C9: LIMPIEZA, AMARRE Y VERIFICACION DEL ESTADO | D9: 0 | E9: 0 | F9: 1 | G9: 0 | H9: 1 | I9: 0 | J9: 0 | K9: 0 | L9: 0 | M9: 0 | N9: 0 | O9: 0 | P9: 1 | Q9: 0.5 | R9: 1 | S9: 8 | T9: 0 | U9: 0 | V9: 0 | W9: 8
A10: 9 | B10: LUB.CHUMACERAS | C10: LUBRICAR CHUMACERAS, EJE Y BUJES | D10: 0 | E10: 0 | F10: 0 | G10: 0 | H10: 0 | I10: 0 | J10: 0 | K10: 0 | L10: 1 | M10: 0 | N10: 0 | O10: 0 | P10: 1 | Q10: 1 | R10: 1 | S10: 9 | T10: 0 | U10: 0 | V10: 0 | W10: 9
A11: 10 | B11: DUCTOS Y CUELLO | C11: LIMPIEZA, VERIFICACION DEL ESTADO | D11: 0 | E11: 0 | F11: 1 | G11: 0 | H11: 0 | I11: 0 | J11: 0 | K11: 0 | L11: 0 | M11: 0 | N11: 0 | O11: 0 | P11: 1 | Q11: 0.5 | R11: 1 | S11: 10 | T11: 0 | U11: 0 | V11: 0 | W11: 10
A12: 11 | B12: SERPENTIN EVAPORADOR | C12: LIMPIEZA Y DESENCRUSTE | D12: 1 | E12: 0 | F12: 1 | G12: 0 | H12: 0 | I12: 0 | J12: 0 | K12: 0 | L12: 0 | M12: 0 | N12: 0 | O12: 0 | P12: 1 | Q12: 15 | R12: 1 | S12: 11 | T12: 0 | U12: 0 | V12: 0 | W12: 11
A13: 12 | B13: VALVULA EXPANCION | C13: REVISAR EL ESTADO Y FUGA DE LA VALVULA | D13: 0 | E13: 0 | F13: 0 | G13: 0 | H13: 0 | I13: 0 | J13: 0 | K13: 0 | L13: 0 | M13: 0 | N13: 0 | O13: 0 | P13: 1 | Q13: 0.5 | R13: 1 | S13: 12 | T13: 0 | U13: 0 | V13: 0 | W13: 12
... A61: 60 | B61: CORREAS | C61: VERIFICACION | D61: 0 | E61: 0 | F61: 0 | G61: 0 | H61: 0 | I61: 0 | J61: 0 | K61: 0 | L61: 0 | M61: 0 | N61: 0 | O61: 0 | P61: 1 | Q61: 0.5 | R61: 1 | S61: 60 | T61: 0 | U61: 0 | V61: 0 | W61: 60
A62: 61 | B62: LUB.EJES,BUJES Y CHUMACERAS | D62: 0 | E62: 0 | F62: 0 | G62: 0 | H62: 0 | I62: 0 | J62: 0 | K62: 0 | L62: 0 | M62: 0 | N62: 0 | O62: 0 | P62: 1 | Q62: 0 | R62: 0 | S62: 61 | T62: 0 | U62: 0 | V62: 0 | W62: 61
A63: 62 | B63: MONITOR DE FASE | C63: VERIFICACION | D63: 0 | E63: 0 | F63: 0 | G63: 0 | H63: 0 | I63: 0 | J63: 0 | K63: 0 | L63: 0 | M63: 0 | N63: 0 | O63: 0 | P63: 1 | Q63: 0.5 | R63: 1 | S63: 62 | T63: 0 | U63: 0 | V63: 0 | W63: 62
A64: 63 | B64: SUPER ARRANCADOR | C64: VERIFICACION | D64: 0 | E64: 0 | F64: 0 | G64: 0 | H64: 0 | I64: 0 | J64: 0 | K64: 0 | L64: 0 | M64: 0 | N64: 0 | O64: 0 | P64: 1 | Q64: 0.5 | R64: 1 | S64: 63 | T64: 0 | U64: 0 | V64: 0 | W64: 63
A65: 757 | B65: BORNERA COMPRESOR | D65: 0 | E65: 0 | F65: 0 | G65: 0 | H65: 0 | I65: 0 | J65: 0 | K65: 0 | L65: 0 | M65: 0 | N65: 0 | O65: 0 | P65: 4 | Q65: 0 | R65: 0 | S65: 1 | T65: 0 | U65: 0 | V65: 0 | W65: 757
A66: 758 | B66: VALVULAS DE SUCCION | D66: 0 | E66: 0 | F66: 0 | G66: 0 | H66: 0 | I66: 0 | J66: 0 | K66: 0 | L66: 0 | M66: 0 | N66: 0 | O66: 0 | P66: 4 | Q66: 0 | R66: 0 | S66: 2 | T66: 0 | U66: 0 | V66: 0 | W66: 758
A67: 759 | B67: VALVULA DE DESCARGA | D67: 0 | E67: 0 | F67: 0 | G67: 0 | H67: 0 | I67: 0 | J67: 0 | K67: 0 | L67: 0 | M67: 0 | N67: 0 | O67: 0 | P67: 4 | Q67: 0 | R67: 0 | S67: 3 | T67: 0 | U67: 0 | V67: 0 | W67: 759
A68: 760 | B68: VALVULAS DE LIQUIDO | D68: 0 | E68: 0 | F68: 0 | G68: 0 | H68: 0 | I68: 0 | J68: 0 | K68: 0 | L68: 0 | M68: 0 | N68: 0 | O68: 0 | P68: 4 | Q68: 0 | R68: 0 | S68: 4 | T68: 0 | U68: 0 | V68: 0 | W68: 760
A69: 761 | B69: MIRILLA DE LIQUIDO | D69: 0 | E69: 0 | F69: 0 | G69: 0 | H69: 0 | I69: 0 | J69: 0 | K69: 0 | L69: 0 | M69: 0 | N69: 0 | O69: 0 | P69: 4 | Q69: 0 | R69: 0 | S69: 5 | T69: 0 | U69: 0 | V69: 0 | W69: 761
A70: 762 | B70: NIVEL DE ACEITE | D70: 0 | E70: 0 | F70: 0 | G70: 0 | H70: 0 | I70: 0 | J70: 0 | K70: 0 | L70: 0 | M70: 0 | N70: 0 | O70: 0 | P70: 4 | Q70: 0 | R70: 0 | S70: 6 | T70: 0 | U70: 0 | V70: 0 | W70: 762
A71: 763 | B71: SEPARADOR DE ACEITE | D71: 0 | E71: 0 | F71: 0 | G71: 0 | H71: 0 | I71: 0 | J71: 0 | K71: 0 | L71: 0 | M71: 0 | N71: 0 | O71: 0 | P71: 4 | Q71: 0 | R71: 0 | S71: 7 | T71: 0 | U71: 0 | V71: 0 | W71: 763
A72: 764 | B72: FILTRO DE ACEITE | D72: 0 | E72: 0 | F72: 0 | G72: 0 | H72: 0 | I72: 0 | J72: 0 | K72: 0 | L72: 0 | M72: 0 | N72: 0 | O72: 0 | P72: 4 | Q72: 0 | R72: 0 | S72: 8 | T72: 0 | U72: 0 | V72: 0 | W72: 764
A73: 765 | B73: CONTROL DE PRESION DE ACEITE | D73: 0 | E73: 0 | F73: 0 | G73: 0 | H73: 0 | I73: 0 | J73: 0 | K73: 0 | L73: 0 | M73: 0 | N73: 0 | O73: 0 | P73: 4 | Q73: 0 | R73: 0 | S73: 9 | T73: 0 | U73: 0 | V73: 0 | W73: 765
A74: 766 | B74: PRUEBA ACIDEZ ACEITE | D74: 0 | E74: 0 | F74: 0 | G74: 0 | H74: 0 | I74: 0 | J74: 0 | K74: 0 | L74: 0 | M74: 0 | N74: 0 | O74: 0 | P74: 4 | Q74: 0 | R74: 0 | S74: 10 | T74: 0 | U74: 0 | V74: 0 | W74: 766
A75: 767 | B75: AISLAMIENTO TUBERIA | D75: 0 | E75: 0 | F75: 0 | G75: 0 | H75: 0 | I75: 0 | J75: 0 | K75: 0 | L75: 0 | M75: 0 | N75: 0 | O75: 0 | P75: 4 | Q75: 0 | R75: 0 | S75: 11 | T75: 0 | U75: 0 | V75: 0 | W75: 767
A76: 768 | B76: SOPORTES | D76: 0 | E76: 0 | F76: 0 | G76: 0 | H76: 0 | I76: 0 | J76: 0 | K76: 0 | L76: 0 | M76: 0 | N76: 0 | O76: 0 | P76: 4 | Q76: 0 | R76: 0 | S76: 12 | T76: 0 | U76: 0 | V76: 0 | W76: 768
... A155: 999 | B155: VIBRACIONES Y RUIDO | D155: 0 | E155: 0 | F155: 0 | G155: 0 | H155: 1 | I155: 30 | J155: 0 | K155: 0 | L155: 0 | M155: 0 | N155: 0 | O155: 0 | P155: 16 | Q155: 0 | R155: 0 | S155: 15 | T155: 0 | U155: 0 | V155: 0 | W155: 1075
A156: 1 | D156: 1 | E156: 0 | F156: 0 | G156: 0 | H156: 0 | I156: 0 | J156: 0 | K156: 0 | L156: 0 | M156: 0 | N156: 0 | O156: 0 | P156: 1 | Q156: 0 | R156: 0 | S156: 0 | T156: 0 | U156: 0 | V156: 0 | W156: 1146
A157: 1000 | B157: TARJETA | D157: 0 | E157: 0 | F157: 1 | G157: 30 | H157: 0 | I157: 0 | J157: 0 | K157: 0 | L157: 0 | M157: 0 | N157: 0 | O157: 0 | P157: 16 | Q157: 0 | R157: 0 | S157: 16 | T157: 0 | U157: 0 | V157: 0 | W157: 1076
A158: 1001 | B158: BORNERA COMPRESOR | D158: 0 | E158: 0 | F158: 0 | G158: 0 | H158: 1 | I158: 30 | J158: 0 | K158: 0 | L158: 0 | M158: 0 | N158: 0 | O158: 0 | P158: 16 | Q158: 0 | R158: 0 | S158: 17 | T158: 0 | U158: 0 | V158: 0 | W158: 1077
A159: 1002 | B159: SOPORTES MOTOR | D159: 0 | E159: 0 | F159: 1 | G159: 30 | H159: 0 | I159: 0 | J159: 0 | K159: 0 | L159: 0 | M159: 0 | N159: 0 | O159: 0 | P159: 16 | Q159: 0 | R159: 0 | S159: 18 | T159: 0 | U159: 0 | V159: 0 | W159: 1078
A160: 1003 | B160: HELICE | D160: 0 | E160: 0 | F160: 1 | G160: 30 | H160: 1 | I160: 30 | J160: 0 | K160: 0 | L160: 0 | M160: 0 | N160: 0 | O160: 0 | P160: 16 | Q160: 0 | R160: 0 | S160: 19 | T160: 0 | U160: 0 | V160: 0 | W160: 1079
A161: 1004 | B161: ACOMETIDA ELECTRICA | D161: 0 | E161: 0 | F161: 1 | G161: 30 | H161: 0 | I161: 0 | J161: 0 | K161: 0 | L161: 0 | M161: 0 | N161: 0 | O161: 0 | P161: 16 | Q161: 0 | R161: 0 | S161: 20 | T161: 0 | U161: 0 | V161: 0 | W161: 1080
A162: 1005 | B162: TERMINALES | D162: 0 | E162: 0 | F162: 0 | G162: 0 | H162: 1 | I162: 30 | J162: 0 | K162: 0 | L162: 0 | M162: 0 | N162: 0 | O162: 0 | P162: 16 | Q162: 0 | R162: 0 | S162: 21 | T162: 0 | U162: 0 | V162: 0 | W162: 1081
A163: 1006 | B163: CARCASA | D163: 0 | E163: 0 | F163: 1 | G163: 30 | H163: 0 | I163: 0 | J163: 0 | K163: 0 | L163: 0 | M163: 0 | N163: 0 | O163: 0 | P163: 16 | Q163: 0 | R163: 0 | S163: 22 | T163: 0 | U163: 0 | V163: 0 | W163: 1082
A164: 1007 | B164: BORNES MOTOR | D164: 0 | E164: 0 | F164: 0 | G164: 0 | H164: 1 | I164: 30 | J164: 0 | K164: 0 | L164: 0 | M164: 0 | N164: 0 | O164: 0 | P164: 16 | Q164: 0 | R164: 0 | S164: 23 | T164: 0 | U164: 0 | V164: 0 | W164: 1083
A165: 1008 | B165: CARETA | D165: 0 | E165: 0 | F165: 1 | G165: 30 | H165: 1 | I165: 30 | J165: 0 | K165: 0 | L165: 0 | M165: 0 | N165: 0 | O165: 0 | P165: 16 | Q165: 0 | R165: 0 | S165: 24 | T165: 0 | U165: 0 | V165: 0 | W165: 1084
...

Sheet Hoja3
A2: codigo | B2: actividad | C2: descripcion | D2: diferenciar
A3: PREG1 | B3: Verifique problemas operacionales con el cliente ruidos y vibraciones anormales | C3: =VLOOKUP(A3,actividades!$A$3:$B$3633,2,0) -> Verifique problemas operacionales con el cliente ruidos y vibraciones anormales | D3: =IF(B3<>C3,"DIFERENTE","")
A4: PREG1 | B4: Verifique problemas operacionales con el cliente- ruidos y vibraciones anormales | C4: =VLOOKUP(A4,actividades!$A$3:$B$3633,2,0) -> Verifique problemas operacionales con el cliente ruidos y vibraciones anormales | D4: =IF(B4<>C4,"DIFERENTE","") -> DIFERENTE
A5: PREG10 | B5: Registrar y verifique corriente y voltaje de todos los motores y compresor(es) | C5: =VLOOKUP(A5,actividades!$A$3:$B$3633,2,0) -> Verificar condensaciones externas y anómalas. | D5: =IF(B5<>C5,"DIFERENTE","") -> DIFERENTE
A6: PREG102 | B6: Verificar funcionamiento de todos los motores | C6: =VLOOKUP(A6,actividades!$A$3:$B$3633,2,0) -> Comprobar switch de flujo | D6: =IF(B6<>C6,"DIFERENTE","") -> DIFERENTE
A7: PREG104 | B7: Limpiar superficies de las aletas. Verificar presiones antes y después del servicio. | C7: =VLOOKUP(A7,actividades!$A$3:$B$3633,2,0) -> Registrar la presión de entrada y salida de agua de agua | D7: =IF(B7<>C7,"DIFERENTE","") -> DIFERENTE
A8: PREG105 | B8: Inspeccionar daños en las aletas | C8: =VLOOKUP(A8,actividades!$A$3:$B$3633,2,0) -> Verificar con el cliente estado de funcionamiento del equipo. | D8: =IF(B8<>C8,"DIFERENTE","") -> DIFERENTE
A9: PREG1062 | B9: Nivel de ruido | C9: =VLOOKUP(A9,actividades!$A$3:$B$3633,2,0) -> Nivel de ruido | D9: =IF(B9<>C9,"DIFERENTE","")
A10: PREG1065 | B10: Verificación rastros de fugas | C10: =VLOOKUP(A10,actividades!$A$3:$B$3633,2,0) -> Verificación rastros de fugas | D10: =IF(B10<>C10,"DIFERENTE","")
A11: PREG1067 | B11: Limpiar drenaje | C11: =VLOOKUP(A11,actividades!$A$3:$B$3633,2,0) -> Limpiar drenaje | D11: =IF(B11<>C11,"DIFERENTE","")
A12: PREG1069 | B12: Verificar operación válvula de control | C12: =VLOOKUP(A12,actividades!$A$3:$B$3633,2,0) -> Verificar operación válvula de control | D12: =IF(B12<>C12,"DIFERENTE","")
A13: PREG107 | B13: Serpentín evaporador inspeccione el serpentín | C13: =VLOOKUP(A13,actividades!$A$3:$B$3633,2,0) -> Revisar acumulación polvo en serpentín evaporador. | D13: =IF(B13<>C13,"DIFERENTE","") -> DIFERENTE
A14: PREG1073 | B14: Verificación rastros de fugas | C14: =VLOOKUP(A14,actividades!$A$3:$B$3633,2,0) -> Verificación rastros de fugas | D14: =IF(B14<>C14,"DIFERENTE","")
... A1378: PREG99 | B1378: Inspeccionar y ajustar correas y poleas (si aplica) | C1378: =VLOOKUP(A1378,actividades!$A$3:$B$3633,2,0) -> Verificar filtro | D1378: =IF(B1378<>C1378,"DIFERENTE","") -> DIFERENTE

Sheet actividades
A2: codigo | B2: actividad | C2: dias | D2: cliente | E2: usuario | F2: fechagr | G2: id
A3: PREG1 | B3: Verifique problemas operacionales con el cliente ruidos y vibraciones anormales | C3: 0 | F3: 43768.367 | G3: 1
A4: PREG10 | B4: Verificar condensaciones externas y anómalas. | C4: 0 | F4: 43768.367 | G4: 10
A5: PREG100 | B5: Inspección y limpieza de gabinete manejadora de requerirse | C5: 0 | F5: 43768.367 | G5: 100
A6: PREG101 | B6: Inspeccionar limpieza. residuos y caja de control. Ajuste de terminaciones. Limpiar y apretar según necesidad | C6: 0 | F6: 43768.367 | G6: 101
A7: PREG102 | B7: Comprobar switch de flujo | C7: 0 | F7: 43768.367 | G7: 102
A8: PREG103 | B8: Registrar la temperatura de entrada y salida de agua | C8: 0 | F8: 43768.367 | G8: 103
A9: PREG104 | B9: Registrar la presión de entrada y salida de agua de agua | C9: 0 | F9: 43768.367 | G9: 104
A10: PREG1041 | B10: Ajustar acoples. poleas y bandas. | C10: 90 | F10: 44417.457 | G10: 1041
A11: PREG1042 | B11: Inspeccionar los relés. fusibles. bobina. presostatos. breaker. switch. resistencia y termostato. | C11: 60 | F11: 44417.457 | G11: 1042
A12: PREG1043 | B12: Inspeccionar acoples. poleas y correas. | C12: 90 | F12: 44417.457 | G12: 1043
A13: PREG1044 | B13: Inspeccionar el evaporador y motor blower. | C13: 60 | F13: 44417.457 | G13: 1044
A14: PREG1045 | B14: Inspeccionar. limpiar o cambiar filtros (según requiera). | C14: 90 | F14: 44417.457 | G14: 1045
... A2161: PREG322 | B2161: Revisar estado de las aletas en condensador | C2161: 0 | F2161: 43768.367 | G2161: 322
A2162: PREG3227 | B2162: (B)Ajuste de tortillería | C2162: 0 | D2162: EPM 1990081-02 | F2162: 45112.897 | G2162: 3227
A2163: PREG3228 | B2163: (M) Ajuste de válvula flotadora | C2163: 0 | D2163: EPM 1990081-02 | F2163: 45112.897 | G2163: 3228
A2164: PREG3229 | B2164: (T) Ajuste y desulfatación de terminales eléctricas y conexiones | C2164: 0 | D2164: EPM 1990081-02 | F2164: 45112.897 | G2164: 3229
A2165: PREG323 | B2165: Revisar operación del termostato | C2165: 0 | F2165: 43768.367 | G2165: 323
A2166: PREG3230 | B2166: (T) Amperaje L1 - L2 | C2166: 0 | D2166: EPM 1990081-02 | F2166: 45112.897 | G2166: 3230
A2167: PREG3231 | B2167: (A) Análisis del aceite del compresor para determinar cambio | C2167: 0 | D2167: EPM 1990081-02 | F2167: 45112.897 | G2167: 3231
A2168: PREG3232 | B2168: (M) Backup de programación y mímicos | C2168: 0 | D2168: EPM 1990081-02 | F2168: 45112.897 | G2168: 3232
A2169: PREG3233 | B2169: (B)Chequear sistema de control | C2169: 0 | D2169: EPM 1990081-02 | F2169: 45112.897 | G2169: 3233
A2170: PREG3234 | B2170: (M) Chequeo alineación de poleas y bandas con herramienta digital | C2170: 0 | D2170: EPM 1990081-02 | F2170: 45112.897 | G2170: 3234
A2171: PREG3235 | B2171: (M) Chequeo de nivel de agua | C2171: 0 | D2171: EPM 1990081-02 | F2171: 45112.897 | G2171: 3235
A2172: PREG3236 | B2172: (M) Chequeo funcionamiento bomba | C2172: 0 | D2172: EPM 1990081-02 | F2172: 45112.897 | G2172: 3236
A2173: PREG3237 | B2173: (T) Chequeo mirilla de líquido (si aplica) | C2173: 0 | D2173: EPM 1990081-02 | F2173: 45112.897 | G2173: 3237
A2174: PREG3238 | B2174: (M) Chequeo rodamientos motor | C2174: 0 | D2174: EPM 1990081-02 | F2174: 45112.897 | G2174: 3238
A2175: PREG3239 | B2175: (M) Chequeo ventilador | C2175: 0 | D2175: EPM 1990081-02 | F2175: 45112.897 | G2175: 3239
A2176: PREG324 | B2176: Revisar ruidos o condiciones anormales en ventilador. motor y compresor. Identificar causa | C2176: 0 | F2176: 43768.367 | G2176: 324
A2177: PREG3240 | B2177: (T) Compresor #1 Lectura de Amperaje: RS - RT - ST | C2177: 0 | D2177: EPM 1990081-02 | F2177: 45112.897 | G2177: 3240
A2178: PREG3241 | B2178: (T) Compresor #1 Lectura de Presión (PSI) succión - descarga | C2178: 0 | D2178: EPM 1990081-02 | F2178: 45112.897 | G2178: 3241
A2179: PREG3242 | B2179: (T) Compresor #1 Lectura de Temperatura (°C) succión - descarga | C2179: 0 | D2179: EPM 1990081-02 | F2179: 45112.897 | G2179: 3242
A2180: PREG3243 | B2180: (T) Compresor #1 Lectura de Voltaje: L1 - L2 - L3 | C2180: 0 | D2180: EPM 1990081-02 | F2180: 45112.897 | G2180: 3243
A2181: PREG3244 | B2181: (T) Compresor #2 Lectura de Amperaje: RS - RT - ST | C2181: 0 | D2181: EPM 1990081-02 | F2181: 45112.897 | G2181: 3244
A2182: PREG3245 | B2182: (T) Compresor #2 Lectura de Presión (PSI) succión - descarga | C2182: 0 | D2182: EPM 1990081-02 | F2182: 45112.897 | G2182: 3245
A2183: PREG3246 | B2183: (T) Compresor #2 Lectura de Temperatura (°C) succión - descarga | C2183: 0 | D2183: EPM 1990081-02 | F2183: 45112.897 | G2183: 3246
A2184: PREG3247 | B2184: (T) Compresor #2 Lectura de Voltaje: L1 - L2 - L3 | C2184: 0 | D2184: EPM 1990081-02 | F2184: 45112.897 | G2184: 3247
A2185: PREG3248 | B2185: (T) Compresor: Amperaje L1 - L2 Voltaje: RS | C2185: 0 | D2185: EPM 1990081-02 | F2185: 45112.897 | G2185: 3248
A2186: PREG3249 | B2186: (T) Comprobación oper. de las válvulas de exp. termostáticas | C2186: 0 | D2186: EPM 1990081-02 | F2186: 45112.897 | G2186: 3249
A2187: PREG325 | B2187: Inspeccionar la bandeja de condensado y limpie si es necesario | C2187: 0 | F2187: 43768.367 | G2187: 325
...
