Workbook

Sheet 1001 OK
B1: 1001 | C1: Pagos o abonos en cuenta y retenciones practicadas V10
N2: 169 Colombia | O2: VALOR DE LA COMPRA DESCONTADO NOTA CREDITO
B3: Concepto | C3: Tipo de documento | D3: Número identificación del informado | E3: tipo | F3: Primer apellido del informado | G3: Segundo apellido del informado | H3: Primer nombre del informado | I3: Otros nombres del informado | J3: Razón social informado | K3: Dirección | L3: Código dpto. | M3: Código mcp | N3: País de residencia o domicilio | O3: Pago o abono en cuenta deducible | Q3: Pago o abono en cuenta NO deducible | R3: Iva mayor valor del costo o gasto deducible | S3: Iva mayor valor del costo o gasto no deducible | U3: Retención en la fuente practicada renta | V3: Retención en la fuente practicada IVA régimen común | W3: Retención en la fuente practicada IVA no domiciliados
A4: 1 | B4: 5007 | C4: 31 | D4: 805011074 | E4: 31 | J4: ADIDAS COLOMBIA LTDA | N4: 169 | O4: 2823025 | P4: 0 | Q4: 0 | R4: 0 | S4: 0 | T4: 0 | U4: 0 | V4: 0 | W4: 0
A5: 2 | B5: 5007 | C5: 31 | D5: 900128596 | E5: #N/A | F5: #N/A | G5: #N/A | H5: #N/A | I5: #N/A | J5: AGRO PEREZ S.A.S | K5: #N/A | L5: #N/A | M5: #N/A | N5: 169 | O5: 686030 | P5: 0 | Q5: 0 | R5: 0 | S5: 0 | T5: 0 | U5: 0 | V5: 0 | W5: 0
A6: 3 | B6: 5007 | C6: 31 | D6: 901073241 | E6: 31 | J6: AGROTECNICO J.O. SAS - BULERIAS | K6: CRA 7 N 5-55 | N6: 169 | O6: 263561 | P6: 0 | Q6: 0 | R6: 0 | S6: 0 | T6: 0 | U6: 0 | V6: 0 | W6: 0
A7: 4 | B7: 5007 | C7: 31 | D7: 860013771 | E7: 31 | J7: AJOVER DARNEL S.A.S. | K7: TRANSVERSAL 93 N° 65A-30 | N7: 169 | O7: 13702300 | P7: 0 | Q7: 0 | R7: 0 | S7: 0 | T7: 0 | U7: 0 | V7: 0 | W7: 0
A8: 5 | B8: 5007 | C8: 13 | D8: 13720777 | E8: #N/A | F8: #N/A | G8: #N/A | H8: #N/A | I8: #N/A | J8: ALEXANDER PALOMINO | K8: #N/A | L8: #N/A | M8: #N/A | N8: 169 | O8: 3492000 | P8: 0 | Q8: 0 | R8: 0 | S8: 0 | T8: 0 | U8: 0 | V8: 0 | W8: 0
A9: 6 | B9: 5007 | C9: 13 | D9: 1126038685 | E9: 13 | F9: EL REDA | G9: AWADA | H9: ALI | I9: RIAD | J9: ALI RIAD EL REDA AWADA | N9: 169 | O9: 16354484 | P9: 0 | Q9: 0 | R9: 0 | S9: 0 | T9: 0 | U9: 0 | V9: 0 | W9: 0
A10: 7 | B10: 5007 | C10: 31 | D10: 901368217 | E10: 31 | J10: ALIANZA MEGA GROUP S.A.S. | K10: CRA 77 C 48 B 208 PISO 2 | L10: 05 | M10: 001 | N10: 169 | O10: 1576635 | P10: 0 | Q10: 0 | R10: 0 | S10: 0 | T10: 0 | U10: 0 | V10: 0 | W10: 0
A11: 8 | B11: 5007 | C11: 31 | D11: 800160395 | E11: 31 | J11: ALMACEN Y DISTRIBUIDORA GONZALEZ S.A.S. | K11: CR 42 32 28 | L11: 08 | M11: 001 | N11: 169 | O11: 20732857 | P11: 0 | Q11: 0 | R11: 0 | S11: 0 | T11: 0 | U11: 0 | V11: 0 | W11: 0
A12: 9 | B12: 5007 | C12: 31 | D12: 901252634 | E12: #N/A | F12: #N/A | G12: #N/A | H12: #N/A | I12: #N/A | J12: Aluminios Super Golden SAS | K12: #N/A | L12: #N/A | M12: #N/A | N12: 169 | O12: 7772138 | P12: 0 | Q12: 0 | R12: 0 | S12: 0 | T12: 0 | U12: 0 | V12: 0 | W12: 0
A13: 10 | B13: 5007 | C13: 31 | D13: 13458366 | E13: #N/A | F13: #N/A | G13: #N/A | H13: #N/A | I13: #N/A | J13: ALVARO GAMBOA PRADA | K13: #N/A | L13: #N/A | M13: #N/A | N13: 169 | O13: 13055097 | P13: 0 | Q13: 0 | R13: 0 | S13: 0 | T13: 0 | U13: 0 | V13: 0 | W13: 0
A14: 11 | B14: 5007 | C14: 31 | D14: 900628277 | E14: #N/A | F14: #N/A | G14: #N/A | H14: #N/A | I14: #N/A | J14: AMERICAN APPAREL COLOMBIA SAS | K14: #N/A | L14: #N/A | M14: #N/A | N14: 169 | O14: 2570740 | P14: 0 | Q14: 0 | R14: 0 | S14: 0 | T14: 0 | U14: 0 | V14: 0 | W14: 0
A15: 12 | B15: 5007 | C15: 31 | D15: 43787151 | E15: #N/A | F15: #N/A | G15: #N/A | H15: #N/A | I15: #N/A | J15: ANA MARIA GALLEGO QUINTERO | K15: #N/A | L15: #N/A | M15: #N/A | N15: 169 | O15: 2621880 | P15: 0 | Q15: 0 | R15: 0 | S15: 0 | T15: 0 | U15: 0 | V15: 0 | W15: 0
A16: 13 | B16: 5007 | C16: 31 | D16: 57300574 | E16: 13 | F16: LOZADA | G16: DE PLATA | H16: ANA | I16: PAULINA | J16: ANA PAULINA LOZADA DE PLATA | N16: 169 | O16: 11397059 | P16: 0 | Q16: 0 | R16: 0 | S16: 0 | T16: 0 | U16: 0 | V16: 0 | W16: 0
A17: 14 | B17: 5007 | C17: 31 | D17: 39432192 | E17: #N/A | F17: #N/A | G17: #N/A | H17: #N/A | I17: #N/A | J17: ANGELA MARIA OTALVARO OROZCO | K17: #N/A | L17: #N/A | M17: #N/A | N17: 169 | O17: 120900 | P17: 0 | Q17: 0 | R17: 0 | S17: 0 | T17: 0 | U17: 0 | V17: 0 | W17: 0
A18: 15 | B18: 5007 | C18: 31 | D18: 860002184 | E18: 31 | J18: AXA COLPATRIA SEGUROS S.A. | N18: 169 | O18: 1063300 | P18: 0 | Q18: 0 | R18: 0 | S18: 0 | T18: 0 | U18: 0 | V18: 0 | W18: 0
A19: 16 | B19: 5007 | C19: 31 | D19: 860000135 | E19: 31 | J19: AZUL K S.A.S. | K19: AUT SUR 60 51 | L19: 11 | M19: 001 | N19: 169 | O19: 13066903 | P19: 0 | Q19: 0 | R19: 0 | S19: 0 | T19: 0 | U19: 0 | V19: 0 | W19: 0
A20: 17 | B20: 5007 | C20: 31 | D20: 1037973102 | E20: 13 | F20: MARIN | G20: DUQUE | H20: BAIRON | J20: BAIRON MARIN DUQUE | N20: 169 | O20: 228500 | P20: 0 | Q20: 0 | R20: 0 | S20: 0 | T20: 0 | U20: 0 | V20: 0 | W20: 0
A21: 18 | B21: 5007 | C21: 31 | D21: 811013231 | E21: #N/A | F21: #N/A | G21: #N/A | H21: #N/A | I21: #N/A | J21: BAZAR DE LA CONSTRUCCION SAS | K21: #N/A | L21: #N/A | M21: #N/A | N21: 169 | O21: 25853411 | P21: 0 | Q21: 0 | R21: 0 | S21: 0 | T21: 0 | U21: 0 | V21: 0 | W21: 0
A22: 19 | B22: 5007 | C22: 31 | D22: 900615349 | E22: 31 | J22: BELLPROF GROUP S.A.S | K22: CALLE 34 N. 43-22 | N22: 169 | O22: 1979654 | P22: 0 | Q22: 0 | R22: 0 | S22: 0 | T22: 0 | U22: 0 | V22: 0 | W22: 0
A23: 20 | B23: 5007 | C23: 31 | D23: 88220927 | E23: 13 | F23: BERMON | G23: CAÑAS | H23: WALTER | I23: ALDEMAR | J23: BERMON CAÑAS WALTER ALDEMAR | K23: CALLE 2 N 5 03 | N23: 169 | O23: 1974790 | P23: 0 | Q23: 0 | R23: 0 | S23: 0 | T23: 0 | U23: 0 | V23: 0 | W23: 0
A24: 21 | B24: 5007 | C24: 31 | D24: 901523051 | E24: #N/A | F24: #N/A | G24: #N/A | H24: #N/A | I24: #N/A | J24: BOMBOFIESTAS SAS | K24: #N/A | L24: #N/A | M24: #N/A | N24: 169 | O24: 334353 | P24: 0 | Q24: 0 | R24: 0 | S24: 0 | T24: 0 | U24: 0 | V24: 0 | W24: 0
A25: 22 | B25: 5007 | C25: 31 | D25: 800066618 | E25: 31 | J25: BRAZZA SPORT S.A.S | K25: CR 56B 49A 29 PISO 15 | N25: 169 | O25: 3983912 | P25: 0 | Q25: 0 | R25: 0 | S25: 0 | T25: 0 | U25: 0 | V25: 0 | W25: 0
A26: 23 | B26: 5007 | C26: 31 | D26: 900586774 | E26: 31 | J26: BRIO IN SAS | K26: CALLE 4 - 14 05 | N26: 169 | O26: 31348224 | P26: 0 | Q26: 0 | R26: 0 | S26: 0 | T26: 0 | U26: 0 | V26: 0 | W26: 0
A27: 24 | B27: 5007 | C27: 31 | D27: 890924167 | E27: 31 | J27: C.I HERMECO S.A | K27: CALLE 49 A N° 55 A-45 INT 1105 | N27: 169 | O27: 1086873 | P27: 0 | Q27: 0 | R27: 0 | S27: 0 | T27: 0 | U27: 0 | V27: 0 | W27: 0
A28: 25 | B28: 5007 | C28: 31 | D28: 901352891 | E28: 31 | J28: CACHARRERIA LOS MARINILLOS DE LA COSTA SAS | K28: CRA 41 N 29 30 BARRANQUILLA | N28: 169 | O28: 47644588 | P28: 0 | Q28: 0 | R28: 0 | S28: 0 | T28: 0 | U28: 0 | V28: 0 | W28: 0
A29: 26 | B29: 5007 | C29: 31 | D29: 901504764 | E29: 31 | J29: CALIFORNIA CTG SAS | K29: CC E INDUSTRIAL TERNERA 1 BODEGA 50 | N29: 169 | O29: 844800 | P29: 0 | Q29: 0 | R29: 0 | S29: 0 | T29: 0 | U29: 0 | V29: 0 | W29: 0
A30: 27 | B30: 5007 | C30: 31 | D30: 32755147 | E30: 13 | F30: LILIANA | G30: MARIA | H30: CANTILLO | I30: PLATA | J30: CANTILLO PLATA LILIANA MARIA | K30: CLE 31 N 40 53 PISO 2 | N30: 169 | O30: 11747534 | P30: 0 | Q30: 0 | R30: 0 | S30: 0 | T30: 0 | U30: 0 | V30: 0 | W30: 0
A31: 28 | B31: 5007 | C31: 31 | D31: 901778121 | E31: 31 | J31: CARIBE S.A.S | K31: CL 34 43 156P 3 BG B 05 | N31: 169 | O31: 649700 | P31: 0 | Q31: 0 | R31: 0 | S31: 0 | T31: 0 | U31: 0 | V31: 0 | W31: 0
A32: 29 | B32: 5007 | C32: 31 | D32: 901358015 | E32: 31 | J32: CASA DEL TEJIDO S.A.S | N32: 169 | O32: 3967895 | P32: 0 | Q32: 0 | R32: 0 | S32: 0 | T32: 0 | U32: 0 | V32: 0 | W32: 0
A33: 30 | B33: 5007 | C33: 31 | D33: 800221591 | E33: #N/A | F33: #N/A | G33: #N/A | H33: #N/A | I33: #N/A | J33: CENTRO ACEROS DEL CARIBE LTDA | K33: #N/A | L33: #N/A | M33: #N/A | N33: 169 | O33: 9315189 | P33: 0 | Q33: 0 | R33: 0 | S33: 0 | T33: 0 | U33: 0 | V33: 0 | W33: 0
A34: 31 | B34: 5007 | C34: 31 | D34: 900158685 | E34: 31 | J34: CENTURY SPORTS SAS | N34: 169 | O34: 575588 | P34: 0 | Q34: 0 | R34: 0 | S34: 0 | T34: 0 | U34: 0 | V34: 0 | W34: 0
A35: 32 | B35: 5007 | C35: 31 | D35: 901151055 | E35: #N/A | F35: #N/A | G35: #N/A | H35: #N/A | I35: #N/A | J35: CERVEH S.A.S. | K35: #N/A | L35: #N/A | M35: #N/A | N35: 169 | O35: 277092 | P35: 0 | Q35: 0 | R35: 0 | S35: 0 | T35: 0 | U35: 0 | V35: 0 | W35: 0
A36: 33 | B36: 5007 | C36: 31 | D36: 901265547 | E36: 31 | J36: CES RED LOGISTICA S.A.S | N36: 169 | O36: 42500 | P36: 0 | Q36: 0 | R36: 0 | S36: 0 | T36: 0 | U36: 0 | V36: 0 | W36: 0
A37: 34 | B37: 5007 | C37: 31 | D37: 15446723 | E37: 13 | F37: BEDOYA | G37: CORRALES | H37: JUAN | I37: DAVID | J37: CICLOORBE BICICLETAS Y TIENDA DEPORTIVA | N37: 169 | O37: 203277 | P37: 0 | Q37: 0 | R37: 0 | S37: 0 | T37: 0 | U37: 0 | V37: 0 | W37: 0
A38: 35 | B38: 5007 | C38: 31 | D38: 900816838 | E38: 31 | J38: CMX S.A.S. | N38: 169 | O38: 84874 | P38: 0 | Q38: 0 | R38: 0 | S38: 0 | T38: 0 | U38: 0 | V38: 0 | W38: 0
A39: 36 | B39: 5007 | C39: 31 | D39: 901422631 | E39: 31 | J39: COLBALONES ZZ 2020 S.A.S 01 00 | K39: CL 37 45 87 | L39: 08 | M39: 001 | N39: 169 | O39: 14532773 | P39: 0 | Q39: 0 | R39: 0 | S39: 0 | T39: 0 | U39: 0 | V39: 0 | W39: 0
A40: 37 | B40: 5007 | C40: 31 | D40: 890900943 | E40: 31 | J40: COLOMBIANA DE COMERCIO S.A. | K40: GRAN ABASTO BG 11 LC 1 | L40: 11 | M40: 001 | N40: 169 | O40: 2185448 | P40: 0 | Q40: 0 | R40: 0 | S40: 0 | T40: 0 | U40: 0 | V40: 0 | W40: 0
...

Sheet terceros
A1: 1 | B1: 2 | C1: 3 | D1: 4 | E1: 5 | F1: 6 | G1: 7 | H1: 8 | I1: 9 | J1: 10
A2: nit | B2: direccion | C2: codDpto | D2: codMunicipio | E2: tipo_doc | F2: razon | G2: apellido1 | H2: apellido2 | I2: nombre1 | J2: nombre2
A3: 901144165 | B3: CL 27 1 07 CAUCASIA ANTIOQUIA | C3: 05 | D3: 154 | E3: 31 | F3: COMPAÑÍA DE TRANSPORTE DE BEBIDAS S.
A4: 901360896 | B4: CALLE 19 12 A 06 | C4: 05 | D4: 380 | E4: 31 | F4: LUBRICANTES EL PAISA S.A.S
A5: 901183779 | B5: CL 12B 21 31 32 BOGOTA | C5: 11 | D5: 001 | E5: 31 | F5: CENTRO DE DIAGNOSTICO AUTOMOTOR SAN RAFAEL
A6: 901130988 | B6: CL 28 20 19 AV LUIS CRLOS GALAN | C6: 05 | D6: 360 | E6: 31 | F6: ESYS SOLUCIONES TECNOLOGICAS S.A.S
A7: 860011153 | B7: CR 45 94 72 | C7: 11 | D7: 001 | E7: 31 | F7: ARL POSITIVA COMPAÑÍA DE SEGUROS
A8: 802022973 | B8: CL 37 1 B 65 | C8: 23 | D8: 001 | E8: 31 | F8: INVERSIONES LOPEZ MIER S.A.S.
A9: 830065179 | B9: CR 58 43 SUR 83 INT 123 | C9: 05 | D9: 001 | E9: 31 | F9: SFA CEBAR S.A.S.
A10: 8364120 | B10: CL 29 40A 25 MONTERIA COL | C10: 23 | D10: 001 | E10: 13 | G10: NIÑO | H10: ALVAREZ | I10: ORLANDO
A11: 900336004 | B11: CL 37 1 B 65 | C11: 23 | D11: 001 | E11: 31 | F11: ADMINISTRADORA COLOMBIANA DE
A12: 830122566 | B12: KM 1 VIA CERETE | C12: 23 | D12: 162 | E12: 31 | F12: COLOMBIA TELECOMUNICACIONES S.A.
A13: 17356123 | B13: CR 43 P SUR 195 OF 1442 | C13: 23 | D13: 001 | E13: 13 | G13: ESCOBAR | H13: MEJIA | I13: EFRAIN
A14: 800157892 | B14: CR 74 79 19 | C14: 08 | D14: 001 | E14: 31 | F14: AUTO ROBLE LTDA.
A15: 892280013 | B15: CRA 27 B CENTRO | C15: 11 | D15: 001 | E15: 31 | F15: CAMARA DE COMERCIO DE SINCELEJO
A16: 900606809 | B16: CR 50 28 A 39 | C16: 05 | D16: 001 | E16: 31 | F16: M BELL S.A.S.
A17: 901182264 | B17: ANILLO VIAL KM 11MAS 520 MTS BG 3 | C17: 54 | D17: 001 | E17: 31 | F17: INDUSTRIAS KAMIPLAST S.A.S.
A18: 900302882 | B18: CL 21 20 52 P1 ST S08 SINCELEJO | C18: 70 | D18: 001 | E18: 31 | F18: SAVANAH RAE COLOMBIA S.A.S.
A19: 900644703 | B19: calle 100 1-25 | C19: 70 | D19: 001 | E19: 31 | F19: INTEGRAL DE BELLEZA CASA DEL ESTILISTA S.A.S
A20: 70696424 | B20: CL 110 9G 520 AV CIRCUNVALAR | C20: 08 | D20: 001 | E20: 13 | G20: CARO | H20: RAMIREZ | I20: NELSON | J20: OCTAVIO
A21: 72139503 | B21: CR 16 12 26 | C21: 20 | D21: 001 | E21: 13 | G21: PACHECO | H21: POLO | I21: ELMER | J21: ENRIQUE
A22: 900488656 | B22: Diago al 44 30 C 04 | C22: 05 | D22: 088 | E22: 31 | F22: VIPERS TECNOLOGIA S.A.S.
A23: 900551822 | B23: CRA 24 18 A 14 BARRIO CENTRO | C23: 08 | D23: 001 | E23: 31 | F23: ALMACEN LA GRANJA DE SAN MARCOS S. A. S
A24: 860020536 | B24: CL 12B 21 31 | C24: 11 | D24: 001 | E24: 31 | F24: BARDOT S.A.S
A25: 900192769 | B25: CL 37 1 B 65 | C25: 23 | D25: 001 | E25: 31 | F25: LLANTAS Y FILTROS SINU S.A.S.
A26: 890905032 | B26: CR 54 46 40 OF 304 | C26: 05 | D26: 001 | E26: 31 | F26: PREBEL S.A.
A27: 900345905 | B27: CL 38 41 71 P2 | C27: 08 | D27: 001 | E27: 31 | F27: GRUPO ISMA S.A.S
A28: 800209088 | B28: CL 43 1C 49 | C28: 70 | D28: 001 | E28: 31 | F28: VIPERS LTDA
A29: 890100725 | B29: CL 108 A 35 A 70 | C29: 08 | D29: 001 | E29: 31 | F29: HAMACAS EL ZAQUE S.A.
A30: 900577348 | B30: KM 36 AUTOPISTA MEDELLIN BOGOTA | C30: 05 | D30: 615 | E30: 31 | F30: MUNDI UTIL S.A.S.
A31: 860020609 | B31: AV I DUSTRIAL CL 19 6905 | C31: 11 | D31: 001 | E31: 31 | F31: LABORATORIOS SMART S A S
A32: 800179834 | B32: AV 37B 42 155 | C32: 05 | D32: 360 | E32: 31 | F32: INVERSIONES SUPPORT S. A.
A33: 70693137 | B33: KM 1 VIA CERETE | C33: 23 | D33: 162 | E33: 13 | G33: GOMEZ | H33: ALZATE | I33: WILLIAM | J33: JOSE
A34: 830512218 | B34: CL 38 4 A 184 MZA 01 | C34: 70 | D34: 001 | E34: 31 | F34: MEDIMARCAS S.A.S.
A35: 10230381 | B35: AV 68 30 06 SUR PS °2 BOGOTA | C35: 11 | D35: 001 | E35: 13 | G35: SUAREZ | H35: GRAJALES | I35: GIRALDO
A36: 70725876 | B36: CR 2 36 35 | C36: 23 | D36: 001 | E36: 13 | G36: LOPEZ | H36: VALENCIA | I36: EFREIN | J36: DE JESUS
A37: 891700037 | B37: CR 57 A 45 39 PS 2 | C37: 05 | D37: 001 | E37: 31 | F37: MAPFRE SEGUROS GENERALES DE COLOMBIA S
A38: 800094742 | B38: CL 38 4 A 184 BL B BG 22 PAR I DUSTRIAL | C38: 70 | D38: 001 | E38: 31 | F38: SURTILINEAS DEL CARIBE S.A.
A39: 8309207 | B39: CL 34 43 70 LC X | C39: 08 | D39: 001 | E39: 13 | G39: ARISTIZABAL | H39: ARISTIZABAL | I39: APOLINAR | J39: ANTONIO
A40: 901265090 | B40: CL 12 5 72 MOTILONES | C40: 54 | D40: 001 | E40: 31 | F40: INVERSIONES CARRASCAL MORA S.A.S
...

Sheet 1003 OK
D1: 1003 Retenciones en la fuente que le practicaron
A2: 1003 | B2: Retenciones en la fuente que le practicaron V7
A4: Concepto | B4: Tipo de documento | C4: Número identificación | D4: DV | E4: Primer apellido del informado | F4: Segundo apellido del informado | G4: Primer nombre del informado | H4: Otros nombres del informado | I4: Razón social informado | J4: Dirección | K4: Código dpto. | L4: Código mcp | M4: Valor acumulado del pago o abono sujeto a retención en la fuente | N4: Retención en la fuente que le practicaron
N14: =+M14*0.04 -> 0

Sheet 1005 OK
I1: IVA EN COMOPRAS DESCONTANDO LA NOTA CREDITO EN COMPRAS
A2: 1005 | B2: Impuesto a las ventas por pagar (descontable) V7 | I2: DESCONTANDO EL IVA DE LA NOTA CREDITO
A3: Sin cuantias minimas
A4: Tipo de Documento | B4: Numero de identificación del informado | C4: DV | D4: Primer apellido del informado | E4: Segundo apellido del informado | F4: Primer nombre del informado | G4: Otros nombres del informado | H4: Razón social informado | I4: Impuesto descontable | J4: IVA resultante por devoluciones en ventas anuladas, rescindidas o resueltas
B5: 892200994 | H5: ALMACEN FERROMOTORES S.A. | I5: 17490203 | J5: 0 | K5: 0
B6: 900623201 | H6: CACHARRERIA MUNDIAL S.A.S. | I6: 6071660 | J6: 0 | K6: 0
B7: 901281934 | H7: CEMENTOS ORIENTE SAS ZOMAC | I7: 2648695 | J7: 0 | K7: 0
B8: 890900943 | H8: COLOMBIANA DE COMERCIO S.A. | I8: 6662850 | J8: 0 | K8: 0
B9: 800066275 | H9: COMERCIAL J.F.I. S.A.S | I9: 451953 | J9: 0 | K9: 0
B10: 900205377 | H10: COMERCIALIZADORA AGROHIERROS S.A | I10: 13079508 | J10: 0 | K10: 0
B11: 900918651 | H11: COMERCIALIZADORA MAC ROYAL - ZOMAC S.A.S. | I11: 7592 | J11: 0 | K11: 0
B12: 900507746 | H12: CONCREACEROS S.A.S. | I12: 9777355 | J12: 0 | K12: 0
B13: 901359284 | H13: COVERFIL S.A.S | I13: 208288 | J13: 0 | K13: 0
B14: 901145515 | H14: DA&ROCH DISTRIBUCIONES S.A.S. | I14: 314861 | J14: 0 | K14: 0
B15: 800023002 | H15: DISREL SAS DISTRIBUCIONES Y REPRESENTACIONES ELEC | I15: 2310215 | J15: 0 | K15: 0
B16: 800185467 | H16: DISTHINNER SAS | I16: 1842521 | J16: 0 | K16: 0
... B61: 800098601 | H61: UNIFEL S.A. | I61: 36985879 | J61: 0 | K61: 0
B62: 79148397 | D62: MOJOCOA | E62: PARADA | F62: JUAN | G62: CARLOS | I62: 878519 | J62: 0 | K62: 0
B63: 10934103 | D63: CORREA | E63: CASTRO | F63: LUIS | G63: CARLOS | I63: 19121432 | J63: 0 | K63: 0
B64: 43785419 | D64: GALLEGO | E64: GOMEZ | F64: MARIA | G64: FLORELBA | I64: 323350 | J64: 0 | K64: 0
B65: 70696078 | D65: GALLEGO | E65: GOMEZ | F65: WILLIAM | G65: DARIO | I65: 59918 | J65: 0 | K65: 0
B66: 70353742 | D66: GIRALDO | E66: MARIN | F66: JOHNY | G66: ANDRES | I66: 326933881 | J66: 0 | K66: 0
B67: 1124060096 | D67: SERHAN | E67: TOUFIC | F67: RABIH | I67: 4485973 | J67: 0 | K67: 0
B68: 9868376 | D68: ZULUAGA | E68: SANCHEZ | F68: FRANK | G68: FERNANDO | I68: 320940 | J68: 0 | K68: 0
B69: 13745511 | D69: PARDO | E69: MILLAN | F69: RUFINO | I69: 97259 | J69: 0 | K69: 0
B70: 70725876 | D70: LOPEZ | E70: VALENCIA | F70: EFREN | G70: DE JESUS | I70: 417042 | J70: 0 | K70: 0
B71: 98483586 | D71: VALENCIA | E71: GARRO | F71: FABIAN | I71: 2315342 | J71: 0 | K71: 0
B72: 1022358313 | D72: ACUA | E72: RODRIGUEZ | F72: CESAR | G72: ALDRIN | I72: 614706 | J72: 0 | K72: 0
B73: 1063169167 | D73: PADILLA | E73: NAVAJA | F73: LINA | G73: MARIA | I73: 463009 | J73: 0 | K73: 0
B74: 1129485999 | D74: FONSECA | E74: JIMENEZ | F74: ROSA | G74: MARIA | I74: 10842805 | J74: 0 | K74: 0
I75: 7.5365094e+08

Sheet 1006 OK
B2: 1006 | C2: Impuesto a las ventas por pagar (generado) e impuesto al consumo V8
B3: El valor del IVA generado y/o el impuesto al consumo de las operaciones donde el valor acumulado del ingreso hubiese sido igual o superior a quinientos mil pesos ($ 500.000)
B4: Tipo de Documento | C4: Numero de identificación | D4: DV | E4: Primer apellido del informado | F4: Segundo apellido del informado | G4: Primer nombre del informado | H4: Otros nombres del informado | I4: Razón social informado | J4: Impuesto generado | K4: IVA recuperado por operaciones en devoluciones en compras anuladas, rescindidas o resueltas | L4: Impuesto al consumo
A5: 1 | B5: 13 | C5: 1079940222 | E5: .CABALLERO | F5: MONTENEGRO | G5: JUAN | H5: MANUEL | J5: 35126 | K5: 0 | L5: 0
A6: 2 | B6: 13 | C6: 1079937378 | E6: .CANTILLO | F6: SANTOS | G6: JESUS | J6: 32013 | K6: 0 | L6: 0
A7: 3 | B7: 13 | C7: 30177198 | E7: .CASTRO | F7: MONTERO | G7: LUZ | J7: 71849 | K7: 0 | L7: 0
A8: 4 | B8: 13 | C8: 1079931569 | E8: .CRESPO | F8: VILLA | G8: CASILDA | J8: 18122 | K8: 0 | L8: 0
A9: 5 | B9: 13 | C9: 1004121069 | E9: .PASION | F9: MARTINEZ | G9: MARIA | H9: EUGENIA | J9: 41864 | K9: 0 | L9: 0
A10: 6 | B10: 13 | C10: 1004120997 | E10: .RODRIGUEZ | F10: RODRIGUEZ | G10: GLENDA | J10: 19080 | K10: 0 | L10: 0
A11: 7 | B11: 13 | C11: 22563210 | E11: ABDALA | F11: DE AVILA | G11: YULIETH | J11: 6371 | K11: 0 | L11: 0
A12: 8 | B12: 13 | C12: 1002302504 | E12: ACEVEDO | F12: MEZA | G12: LUZ | J12: 55435 | K12: 0 | L12: 0
A13: 9 | B13: 13 | C13: 1082844786 | E13: ACEVEDO | G13: YEISON | J13: 16142 | K13: 0 | L13: 0
A14: 10 | B14: 13 | C14: 1004122824 | E14: ACOSTA | F14: PALLARES | G14: CAROLINA | J14: 13763 | K14: 0 | L14: 0
A15: 11 | B15: 13 | C15: 1004123866 | E15: ACOSTA | F15: CANTILLO | G15: CESAR | H15: CAMILO | J15: 19734 | K15: 0 | L15: 0
A16: 12 | B16: 13 | C16: 1079911618 | E16: ACOSTA | G16: MARIA | H16: ELBIRA | J16: 48713 | K16: 0 | L16: 0
A17: 13 | B17: 13 | C17: 1079914290 | E17: ACOSTA | F17: PERTUZ | G17: LUZ | H17: NEIRA | J17: 47101 | K17: 0 | L17: 0
A18: 14 | B18: 13 | C18: 1079932236 | E18: ACOSTA | F18: MONTENEGRO | G18: NEIDER | J18: 15232 | K18: 0 | L18: 0
A19: 15 | B19: 13 | C19: 1079934441 | E19: ACOSTA | G19: YOLANDA | J19: 32715 | K19: 0 | L19: 0
A20: 16 | B20: 13 | C20: 1079935537 | E20: ACOSTA | F20: TORREJANO | G20: LUDYS | J20: 18170 | K20: 0 | L20: 0
A21: 17 | B21: 13 | C21: 1079941789 | E21: ACOSTA | F21: OSORIO | G21: AURA | J21: 4854 | K21: 0 | L21: 0
A22: 18 | B22: 13 | C22: 1082044949 | E22: ACOSTA | F22: VALLE | G22: YURANIS | J22: 65462 | K22: 0 | L22: 0
A23: 19 | B23: 13 | C23: 1082046200 | E23: ACOSTA | F23: VARELA | G23: WENDY | J23: 47261 | K23: 0 | L23: 0
A24: 20 | B24: 13 | C24: 1082046214 | E24: ACOSTA | G24: JESUS | J24: 13891 | K24: 0 | L24: 0
A25: 21 | B25: 13 | C25: 1127573690 | E25: ACOSTA | G25: MARIA | H25: ALEXANDRA | J25: 9117 | K25: 0 | L25: 0
A26: 22 | B26: 13 | C26: 1140849890 | E26: ACOSTA | G26: LILA | J26: 7824 | K26: 0 | L26: 0
A27: 23 | B27: 13 | C27: 1143138834 | E27: ACOSTA | F27: CAMARGO | G27: ENITH | J27: 61423 | K27: 0 | L27: 0
A28: 24 | B28: 13 | C28: 1151923 | E28: ACOSTA | F28: VACA | G28: JULIO | H28: CESAR | J28: 231513 | K28: 0 | L28: 0
A29: 25 | B29: 13 | C29: 19863307 | E29: ACOSTA | F29: ESCORCHA | G29: LUISBETH | H29: YOHANA | J29: 37952 | K29: 0 | L29: 0
A30: 26 | B30: 13 | C30: 22638114 | E30: ACOSTA | F30: SANTODOMINGO | G30: CRISTINA | J30: 9771 | K30: 0 | L30: 0
A31: 27 | B31: 13 | C31: 26825760 | E31: ACOSTA | F31: OROZCO | G31: MAUDIS | J31: 65047 | K31: 0 | L31: 0
A32: 28 | B32: 13 | C32: 26881053 | E32: ACOSTA | G32: YESSICA | J32: 5812 | K32: 0 | L32: 0
A33: 29 | B33: 13 | C33: 32691267 | E33: ACOSTA | F33: BROCHERO | G33: LUZ | H33: MARINA | J33: 132457 | K33: 0 | L33: 0
A34: 30 | B34: 13 | C34: 57300706 | E34: ACOSTA | F34: YANCY | G34: EDITH | J34: 367227 | K34: 0 | L34: 0
A35: 31 | B35: 13 | C35: 57305786 | E35: ACOSTA | F35: BOLAÑO | G35: JUANA | J35: 95639 | K35: 0 | L35: 0
A36: 32 | B36: 13 | C36: 57309594 | E36: ACOSTA | F36: BOLAÑO | G36: YULIS | H36: JOHANA | J36: 107613 | K36: 0 | L36: 0
A37: 33 | B37: 13 | C37: 1079936802 | E37: ACUNA | F37: JIMENEZ | G37: WENDY | J37: 7105 | K37: 0 | L37: 0
A38: 34 | B38: 13 | C38: 57307400 | E38: ACUNA | G38: AURA | H38: MARIA | J38: 9245 | K38: 0 | L38: 0
A39: 35 | B39: 13 | C39: 1010150212 | E39: ACUÑA | F39: MERCADO | G39: VANESA | J39: 3992 | K39: 0 | L39: 0
A40: 36 | B40: 13 | C40: 1081760820 | E40: ACUÑA | F40: MARTINEZ | G40: CELIA | J40: 21507 | K40: 0 | L40: 0
A41: 37 | B41: 13 | C41: 1082044435 | E41: ACUÑA | F41: DE LA MARCA | G41: ENA | J41: 23582 | K41: 0 | L41: 0
...

Sheet iva_ventas
A1: NIT Receptor | B1: Nombre Receptor | C1: iva
A2: 1007162093 | B2: VIVIANA ISABEL OROZCO DAZA | C2: 353600
A3: 1004226846 | B3: DIOSA CARRANZA MAZA | C3: 25195
A4: 26814854 | B4: ABA LUZ CABALLERO | C4: 7983
A5: 901363836 | B5: ABBACÜS BUSINESS SOLUTIONS SAS | C5: 308934
A6: 7598243 | B6: ABEL ANTONIO OROZCO BARON | C6: 49448
A7: 9876305 | B7: ABEL ORTEGA | C7: 53184
A8: 7594734 | B8: ABELARDO CANTILLO ESCALANTE | C8: 122941
A9: 9875160 | B9: ABELARDO ENRIQUE RODRIGUEZ MEDINA | C9: 127731
A10: 5080050 | B10: ABELARDO PABON PACHECO | C10: 237420
A11: 1091683107 | B11: ABRAHAM NAVARRO | C11: 81923
A12: 1081027111 | B12: ABRHAN JOSE NAVARRO PABON | C12: 147657
A13: 49720962 | B13: ADA BORJA DE LA HOZ | C13: 27191
... A630: 1079932094 | B630: CARLOS SEGUNDO MORRON PALMA | C630: 30895
A631: 10010890 | B631: CARLOS SEPULVEDA | C631: 24572
A632: 9875845 | B632: CARLOS SEVERINI | C632: 20996
A633: 1102862027 | B633: CARLOS SOLANO ANAYA | C633: 5588
A634: 7591238 | B634: CARLOS TOMAS SEVERINI CABALLERO | C634: 8702
A635: 1043010456 | B635: CARLOS YEJAS GONZALES | C635: 55180
A636: 7599566 | B636: CARLOS ZAMBRANO | C636: 33689
A637: 1079912216 | B637: CARLOTA AREVALO | C637: 31821
A638: 57308636 | B638: CARLOTA AREVALO CHARRIZ | C638: 47348
A639: 57305548 | B639: CARMELA CASTAÑEDA PARRA | C639: 23359
A640: 26816863 | B640: CARMEN AMPARO LARA DE LA CRUZ | C640: 111429
A641: 22734544 | B641: CARMEN BELIZA CAMPO ORTIZ | C641: 23471
A642: 32732260 | B642: CARMEN BORNACELIS | C642: 7504
A643: 1079913368 | B643: CARMEN CABALLERO CAMPO | C643: 87480
... A694: 1082890050 | B694: CATALINA ESCORCIA | C694: 12438
A695: 84453560 | B695: CEBALLOS SANDOVAL SAMIR ALBERTO | C695: 145789
A696: 26814869 | B696: CECILIA CAALLERO POLO | C696: 9101
A697: 1004120481 | B697: CECILIA CASTRO LLANOS | C697: 45712
A698: 26825482 | B698: CECILIA COLLAZO | C698: 44215
A699: 57308412 | B699: CECILIA ELENA BENAVIDES MEZA | C699: 209160
A700: 57306036 | B700: CECILIA ISABEL DE LA CRUZ PINEDA | C700: 76447
A701: 32782214 | B701: CECILIA ORTEGA MUÑOZ | C701: 31470
A702: 1004380569 | B702: CECILIA SANCHEZ SABALETA | C702: 22592
A703: 1081760820 | B703: CELIA ACUÑA MARTINEZ | C703: 21507
A704: 57303815 | B704: CELIA GAMARRA | C704: 28867
A705: 57309215 | B705: CELIA VALLE MERIÑO | C705: 178824
A706: 45444607 | B706: CELIA YAMITH DE LA CRUZ GARCIA | C706: 307018
...

Sheet 1007 OK
C2: 1007 | D2: Ingresos recibidos V9 | K2: 169 Colombia
C3: Ingresos superiores a $500.000 | L3: subtotal en ventas | M3: subtotal nc en ventas
B4: no | C4: Concepto | D4: Tipo de documento | E4: Número identificación del informado | F4: Primer apellido del informado | G4: Segundo apellido del informado | H4: Primer nombre del informado | I4: Otros nombres del informado | J4: Razón social informado | K4: País de residencia o domicilio | L4: Ingresos brutos recibidos | M4: Devoluciones, rebajas y descuentos
B5: 1 | C5: 4001 | D5: 13 | E5: 1079940222 | F5: .CABALLERO | G5: MONTENEGRO | H5: JUAN | I5: MANUEL | K5: 169 | L5: 184874 | M5: =IFERROR(VLOOKUP(E5,nc_totalizada!$A$3:$D$156,3,0),0) -> 0
B6: 2 | C6: 4001 | D6: 13 | E6: 1079937378 | F6: .CANTILLO | G6: SANTOS | H6: JESUS | K6: 169 | L6: 168487 | M6: =IFERROR(VLOOKUP(E6,nc_totalizada!$A$3:$D$156,3,0),0) -> 0
B7: 3 | C7: 4001 | D7: 13 | E7: 30177198 | F7: .CASTRO | G7: MONTERO | H7: LUZ | K7: 169 | L7: 378151 | M7: =IFERROR(VLOOKUP(E7,nc_totalizada!$A$3:$D$156,3,0),0) -> 0
B8: 4 | C8: 4001 | D8: 13 | E8: 1079931569 | F8: .CRESPO | G8: VILLA | H8: CASILDA | K8: 169 | L8: 95444 | M8: =IFERROR(VLOOKUP(E8,nc_totalizada!$A$3:$D$156,3,0),0) -> 0
B9: 5 | C9: 4001 | D9: 13 | E9: 1004121069 | F9: .PASION | G9: MARTINEZ | H9: MARIA | I9: EUGENIA | K9: 169 | L9: 220402 | M9: =IFERROR(VLOOKUP(E9,nc_totalizada!$A$3:$D$156,3,0),0) -> 0
B10: 6 | C10: 4001 | D10: 13 | E10: 1004120997 | F10: .RODRIGUEZ | G10: RODRIGUEZ | H10: GLENDA | K10: 169 | L10: 100420 | M10: =IFERROR(VLOOKUP(E10,nc_totalizada!$A$3:$D$156,3,0),0) -> 0
B11: 7 | C11: 4001 | D11: 13 | E11: 22563210 | F11: ABDALA | G11: DE AVILA | H11: YULIETH | K11: 169 | L11: 33529 | M11: =IFERROR(VLOOKUP(E11,nc_totalizada!$A$3:$D$156,3,0),0) -> 0
B12: 8 | C12: 4001 | D12: 13 | E12: 1002302504 | F12: ACEVEDO | G12: MEZA | H12: LUZ | K12: 169 | L12: 300095 | M12: =IFERROR(VLOOKUP(E12,nc_totalizada!$A$3:$D$156,3,0),0) -> 0
B13: 9 | C13: 4001 | D13: 13 | E13: 1082844786 | F13: ACEVEDO | H13: YEISON | K13: 169 | L13: 90090 | M13: =IFERROR(VLOOKUP(E13,nc_totalizada!$A$3:$D$156,3,0),0) -> 0
B14: 10 | C14: 4001 | D14: 13 | E14: 1004122824 | F14: ACOSTA | G14: PALLARES | H14: CAROLINA | K14: 169 | L14: 72437 | M14: =IFERROR(VLOOKUP(E14,nc_totalizada!$A$3:$D$156,3,0),0) -> 0
B15: 11 | C15: 4001 | D15: 13 | E15: 1004123866 | F15: ACOSTA | G15: CANTILLO | H15: CESAR | I15: CAMILO | K15: 169 | L15: 103998 | M15: =IFERROR(VLOOKUP(E15,nc_totalizada!$A$3:$D$156,3,0),0) -> 0
B16: 12 | C16: 4001 | D16: 13 | E16: 1079911618 | F16: ACOSTA | H16: MARIA | I16: ELBIRA | K16: 169 | L16: 257187 | M16: =IFERROR(VLOOKUP(E16,nc_totalizada!$A$3:$D$156,3,0),0) -> 0
B17: 13 | C17: 4001 | D17: 13 | E17: 1079914290 | F17: ACOSTA | G17: PERTUZ | H17: LUZ | I17: NEIRA | K17: 169 | L17: 248097 | M17: =IFERROR(VLOOKUP(E17,nc_totalizada!$A$3:$D$156,3,0),0) -> 0
B18: 14 | C18: 4001 | D18: 13 | E18: 1079932236 | F18: ACOSTA | G18: MONTENEGRO | H18: NEIDER | K18: 169 | L18: 80234 | M18: =IFERROR(VLOOKUP(E18,nc_totalizada!$A$3:$D$156,3,0),0) -> 0
B19: 15 | C19: 4001 | D19: 13 | E19: 1079934441 | F19: ACOSTA | H19: YOLANDA | K19: 169 | L19: 172317 | M19: =IFERROR(VLOOKUP(E19,nc_totalizada!$A$3:$D$156,3,0),0) -> 0
B20: 16 | C20: 4001 | D20: 13 | E20: 1079935537 | F20: ACOSTA | G20: TORREJANO | H20: LUDYS | K20: 169 | L20: 95762 | M20: =IFERROR(VLOOKUP(E20,nc_totalizada!$A$3:$D$156,3,0),0) -> 0
B21: 17 | C21: 4001 | D21: 13 | E21: 1079941789 | F21: ACOSTA | G21: OSORIO | H21: AURA | K21: 169 | L21: 25612 | M21: =IFERROR(VLOOKUP(E21,nc_totalizada!$A$3:$D$156,3,0),0) -> 0
B22: 18 | C22: 4001 | D22: 13 | E22: 1082044949 | F22: ACOSTA | G22: VALLE | H22: YURANIS | K22: 169 | L22: 344538 | M22: =IFERROR(VLOOKUP(E22,nc_totalizada!$A$3:$D$156,3,0),0) -> 0
B23: 19 | C23: 4001 | D23: 13 | E23: 1082046200 | F23: ACOSTA | G23: VARELA | H23: WENDY | K23: 169 | L23: 248739 | M23: =IFERROR(VLOOKUP(E23,nc_totalizada!$A$3:$D$156,3,0),0) -> 0
B24: 20 | C24: 4001 | D24: 13 | E24: 1082046214 | F24: ACOSTA | H24: JESUS | K24: 169 | L24: 73109 | M24: =IFERROR(VLOOKUP(E24,nc_totalizada!$A$3:$D$156,3,0),0) -> 0
B25: 21 | C25: 4001 | D25: 13 | E25: 1127573690 | F25: ACOSTA | H25: MARIA | I25: ALEXANDRA | K25: 169 | L25: 48049 | M25: =IFERROR(VLOOKUP(E25,nc_totalizada!$A$3:$D$156,3,0),0) -> 0
B26: 22 | C26: 4001 | D26: 13 | E26: 1140849890 | F26: ACOSTA | H26: LILA | K26: 169 | L26: 41242 | M26: =IFERROR(VLOOKUP(E26,nc_totalizada!$A$3:$D$156,3,0),0) -> 0
B27: 23 | C27: 4001 | D27: 13 | E27: 1143138834 | F27: ACOSTA | G27: CAMARGO | H27: ENITH | K27: 169 | L27: 323409 | M27: =IFERROR(VLOOKUP(E27,nc_totalizada!$A$3:$D$156,3,0),0) -> 0
B28: 24 | C28: 4001 | D28: 13 | E28: 1151923 | F28: ACOSTA | G28: VACA | H28: JULIO | I28: CESAR | K28: 169 | L28: 1218487 | M28: =IFERROR(VLOOKUP(E28,nc_totalizada!$A$3:$D$156,3,0),0) -> 0
B29: 25 | C29: 4001 | D29: 13 | E29: 19863307 | F29: ACOSTA | G29: ESCORCHA | H29: LUISBETH | I29: YOHANA | K29: 169 | L29: 199814 | M29: =IFERROR(VLOOKUP(E29,nc_totalizada!$A$3:$D$156,3,0),0) -> 0
B30: 26 | C30: 4001 | D30: 13 | E30: 22638114 | F30: ACOSTA | G30: SANTODOMINGO | H30: CRISTINA | K30: 169 | L30: 51495 | M30: =IFERROR(VLOOKUP(E30,nc_totalizada!$A$3:$D$156,3,0),0) -> 0
B31: 27 | C31: 4001 | D31: 13 | E31: 26825760 | F31: ACOSTA | G31: OROZCO | H31: MAUDIS | K31: 169 | L31: 342419 | M31: =IFERROR(VLOOKUP(E31,nc_totalizada!$A$3:$D$156,3,0),0) -> 0
B32: 28 | C32: 4001 | D32: 13 | E32: 26881053 | F32: ACOSTA | H32: YESSICA | K32: 169 | L32: 30654 | M32: =IFERROR(VLOOKUP(E32,nc_totalizada!$A$3:$D$156,3,0),0) -> 0
B33: 29 | C33: 4001 | D33: 13 | E33: 32691267 | F33: ACOSTA | G33: BROCHERO | H33: LUZ | I33: MARINA | K33: 169 | L33: 697143 | M33: =IFERROR(VLOOKUP(E33,nc_totalizada!$A$3:$D$156,3,0),0) -> 0
B34: 30 | C34: 4001 | D34: 13 | E34: 57300706 | F34: ACOSTA | G34: YANCY | H34: EDITH | K34: 169 | L34: 1932773 | M34: =IFERROR(VLOOKUP(E34,nc_totalizada!$A$3:$D$156,3,0),0) -> 0
B35: 31 | C35: 4001 | D35: 13 | E35: 57305786 | F35: ACOSTA | G35: BOLAÑO | H35: JUANA | K35: 169 | L35: 503361 | M35: =IFERROR(VLOOKUP(E35,nc_totalizada!$A$3:$D$156,3,0),0) -> 0
B36: 32 | C36: 4001 | D36: 13 | E36: 57309594 | F36: ACOSTA | G36: BOLAÑO | H36: YULIS | I36: JOHANA | K36: 169 | L36: 579787 | M36: =IFERROR(VLOOKUP(E36,nc_totalizada!$A$3:$D$156,3,0),0) -> 0
B37: 33 | C37: 4001 | D37: 13 | E37: 1079936802 | F37: ACUNA | G37: JIMENEZ | H37: WENDY | K37: 169 | L37: 37461 | M37: =IFERROR(VLOOKUP(E37,nc_totalizada!$A$3:$D$156,3,0),0) -> 0
B38: 34 | C38: 4001 | D38: 13 | E38: 57307400 | F38: ACUNA | H38: AURA | I38: MARIA | K38: 169 | L38: 48721 | M38: =IFERROR(VLOOKUP(E38,nc_totalizada!$A$3:$D$156,3,0),0) -> 0
B39: 35 | C39: 4001 | D39: 13 | E39: 1010150212 | F39: ACUÑA | G39: MERCADO | H39: VANESA | K39: 169 | L39: 21008 | M39: =IFERROR(VLOOKUP(E39,nc_totalizada!$A$3:$D$156,3,0),0) -> 0
B40: 36 | C40: 4001 | D40: 13 | E40: 1081760820 | F40: ACUÑA | G40: MARTINEZ | H40: CELIA | K40: 169 | L40: 127259 | M40: =IFERROR(VLOOKUP(E40,nc_totalizada!$A$3:$D$156,3,0),0) -> 0
B41: 37 | C41: 4001 | D41: 13 | E41: 1082044435 | F41: ACUÑA | G41: DE LA MARCA | H41: ENA | K41: 169 | L41: 124184 | M41: =IFERROR(VLOOKUP(E41,nc_totalizada!$A$3:$D$156,3,0),0) -> 0
...

Sheet nc_totalizada
A2: NIT Receptor | B2: Nombre Receptor | C2: subtotal | D2: iva
A3: 10010890 | B3: CARLOS SEPULVEDA | C3: 29412 | D3: 5588
A4: 1002134676 | B4: LAURA FLORES SALAS | C4: 28571 | D4: 5429
A5: 1003313999 | B5: CESAR MANUEL ROMERO MONTERO | C5: 1092437 | D5: 207563
A6: 1004120739 | B6: TONNY JAVIER ANDRADE MEJIA | C6: 66387 | D6: 12613
A7: 1004121396 | B7: JUAN DIEGO PABON | C7: 83007 | D7: 15759
A8: 1004123368 | B8: JULIETH CANO | C8: 503361 | D8: 95639
A9: 1004123373 | B9: MACIEL CANTILLO | C9: 24370 | D9: 4630
A10: 1004123442 | B10: CLAUDIA PEREZ CABALLERO | C10: 43697 | D10: 8303
A11: 1004123792 | B11: JESUS JOSE PEREZ | C11: 57143 | D11: 10857
A12: 1004212863 | B12: NAIROVIS GARCIA OLIVARES | C12: 49580 | D12: 9420
A13: 1004390016 | B13: ERIKA MONTENEGRO MONTERO | C13: 11765 | D13: 2235
A14: 1004434665 | B14: ALEJANDRA PEREZ ZABALETA | C14: 48740 | D14: 9261
... A156: 9876792 | B156: DOLSEY NAVARRO MONTENEGRO | C156: 285714 | D156: 54286
C158: =SUM(C3:C157) -> 27299061 | D158: =SUM(D3:D157) -> 5128758

Sheet 1008 OK
A2: 1008 | B2: Saldo de cuentas por cobrar al 31 de diciembre V7 | M2: 169 Colombia
A4: Concepto | B4: Tipo de documento | C4: Número identificación | D4: DV | E4: Primer apellido deudor | F4: Segundo apellido deudor | G4: Primer nombre deudor | H4: Otros nombres deudor | I4: Razón social deudor | J4: Dirección | K4: Código dpto. | L4: Código mcp | M4: País de residencia o domicilio | N4: Saldo cuentas por cobrar al 31-12

Sheet 1009 OK
A2: 1009 | B2: Saldo de cuentas por pagar al 31 de diciembre V7 | M2: 169 Colombia
A5: Concepto | B5: Tipo de documento | C5: Número identificación | D5: DV | E5: Primer apellido | F5: Segundo apellido | G5: Primer nombre | H5: Otros nombres | I5: Razón social | J5: Dirección | K5: Código dpto. | L5: Código mcp | M5: País de residencia o domicilio | N5: Saldo cuentas por pagar al 31-12

Sheet 1010
A1: 1010 | B1: Información de socios, accionistas, comuneros y/o cooperados V8 | N1: Patrimonio líquido
A2: En cuantía superior a tres millones de pesos ($3.000.000)
A3: Tipo de documento | B3: Número identificación socio o accionista | C3: DV | D3: Primer apellido socio o accionista | E3: Segundo apellido socio o accionista | F3: Primer nombre del socio o accionista | G3: Otros nombres socio o accionista | H3: Razón social | I3: Dirección | J3: Código dpto. | K3: Código mcp | L3: País de residencia o domicilio | M3: Valor patrimonial acciones o aportes al 31-12 | N3: Porcentaje de participación | O3: Porcentaje de participación (posición decimal)

Sheet 1012 OK
A1: 1012 | B1: Información de declaraciones tributarias, acciones y aportes, inversiones en bonos títulos valores y cuentas de ahorro y cuentas corrientes V7
J3: 169 Colombia
A4: Concepto | B4: Tipo de documento | C4: Número de Identificación | D4: DV | E4: Primer apellido del informado | F4: Segundo apellido del informado | G4: Primer nombre del informado | H4: Otros nombres del informado | I4: Razón social informado | J4: Pais de residencia o domicilio | K4: Valor al 31-12

Sheet 2276 0K
B1: 2276 | C1: Información de rentas de trabajo y pensiones V2
A3: Entidad Informante | B3: Tipo de documento del beneficiario | C3: Número de Identificación del beneficiario | D3: Primer Apellido del beneficiario | E3: Segundo Apellido del beneficiario | F3: Primer Nombre del beneficiario | G3: Otros Nombres del beneficiario | H3: Dirección del beneficiario | I3: Departamento del beneficiario | J3: Municipio del beneficiario | K3: País del beneficiario | L3: Pagos por Salarios | M3: Pagos por emolumentos eclesiásticos | N3: Pagos por honorarios | O3: Pagos por servicios | P3: Pagos por comisiones | Q3: Pagos por prestaciones sociales | R3: Pagos por viáticos | S3: Pagos por gastos de representación | T3: Pagos por compensaciones trabajo asociado cooperativo | U3: Otros pagos | V3: Pagos realizados con bonos electrónicos o de papel de servicio, cheques, tarjetas, vales, etc. | W3: Cesantías e intereses de cesantías efectivamente pagadas, consignadas o reconocidas en el periodo | X3: Pensiones de Jubilación, vejez o invalidez | Y3: Aportes Obligatorios por Salud | Z3: Aportes obligatorios a fondos de pensiones y solidaridad pensional y Aportes voluntarios al - RAIS | AA3: Aportes voluntarios a fondos de pensiones voluntarias | AB3: Aportes a cuentas AFC. | AC3: Valor de las retenciones en la fuente por pagos de rentas de trabajo o pensiones

Sheet 1004
A2: 1004 | B2: Descuentos tributarios solicitados V7
A4: Concepto | B4: Tipo de documento | C4: Número identificación | D4: Primer apellido | E4: Segundo apellido | F4: Primer nombre | G4: Otros nombres | H4: Razón social | I4: Dirección | J4: Código dpto. | K4: Código mcp | L4: Código pais | M4: Correo electrónico | N4: Valor del pago o abono en cuenta | O4: Valor del descuento tributario

Sheet 1011
A3: 1011 | B3: Información de las declaraciones tributarias V6
D6: Guía (No hace parte del reporte.)
A7: Concepto | B7: Saldos al -31-12
D8: 8104 | E8: Renta exenta por venta energía eléctrica generada con base en energía eólica, biomasa o residuos agrícolas, solar, geotérmica o de los mares. Art.235-2 numeral 3.
D9: 8106 | E9: Renta exenta por aprovechamiento de nuevas plantaciones forestales incluida la guadua el caucho y el marañón. Art. 235-2 numeral 5_x000D_
D10: 8109 | E10: Renta exenta por prestación de servicio de transporte fluvial con embarcaciones y planchones de bajo calado Art. 235-2 numeral 6.
D11: 8111 | E11: Rentas exentas por la utilidad en la enajenación de predios destinados a fines de utilidad pública. Num 9 Art. 207-2 E.T. Sentencia C-083 del 2018
D12: 8120 | E12: Rentas exentas por aplicación de algún convenio para evitar la doble tributación.
D13: 8121 | E13: Renta exenta por creaciones literarias dela economía naranja contenidas en el artículo 28 de la Ley 98 de 1993. Art. 235-2 numeral 8.
D14: 8125 | E14: Rentas exentas por Intereses, comisiones y pagos por deuda pública externa, E.T. art. 218 E.T.
D15: 8127 | E15: Rentas exentas por inversión en nuevos aserríos, plantas de procesamiento y plantaciones de árboles maderables y árboles en producción de frutos. E.T., art. 235-2, numeral 5.
D16: 8133 | E16: Rentas exentas por servicios prestados en hoteles nuevos. E.T., Art. 207-2, Num 3 Sentencia C 235 del 29 de mayo de 2019
D17: 8134 | E17: Rentas exentas por servicios prestados en hoteles remodelado y/o ampliados. E.T., Art. 207-2 E.T, Num. 4. Sentencia C 235 del 29 de mayo de 2019
D18: 8140 | E18: Rentas exentas por aportes voluntarios a los fondos de pensiones. E.T. art. 126-1, inc. 2
D19: 8141 | E19: Rentas exentas por los ahorros a largo plazo para el fomento de la construcción. E.T., art. 126-4.
... D167: 9210 | E167: Exención en IVA Las bicicletas y sus partes; motocicletas y sus partes y motocarros y sus partes, que se introduzcan y comercialicen en los departamentos de Amazonas, Guainía, Guaviare, Vaupés y Vichada, siempre y cuando se destinen exclusivamente al consumo dentro del mismo departamento. Numeral 6 del art. 477 del E.T.

Sheet 1647 
A2: 1647 | B2: Ingresos recibidos para terceros V2
A3: Sin cuantias minimas | J3: 169 Colombia | X3: 169 Colombia
A4: Concepto | B4: Tipo de documento de quien se recibe el ingreso | C4: Número identificación de quien recibe el ingreso | D4: DV | E4: Primer apellido de quien se recibe el ingreso | F4: Segundo apellido de quien se recibe el ingreso | G4: Primer nombre de quien se recibe el ingreso | H4: Otros nombres de quien se recibe el ingreso | I4: Razón social de quien se recibe el ingreso | J4: País de residencia o domicilio de quien se recibe el ingreso | K4: Valor total de la operación | L4: Valor ingreso reintegrado transferido distribuido al tercero | M4: Valor retención reintegrada transferida distribuida al tercero | N4: Tipo de documento del tercero para quien se recibió el ingreso | O4: Identificación del tercero para quien se recibió el ingreso | P4: Primer apellido del tercero para quien se recibió el ingreso | Q4: Segundo apellido del tercero par quien se recibió el ingreso | R4: Primer nombre del tercero para quien se recibió el ingreso | S4: Otros nombres del tercero para quien se recibió el ingreso | T4: Razón social del tercero para quien se recibió el ingreso | U4: Dirección | V4: Código dpto. | W4: Código mcp | X4: País de residencia o domicilio

Sheet 2275
A2: 2275 | B2: Ingresos no constitutivos de renta ni ganancia ocasional V1
A4: Concepto | B4: Tipo de documento del tercero | C4: Número identificación del tercero | D4: Primer apellido del informado | E4: Segundo apellido del informado | F4: Primer nombre del informado | G4: Otros nombres del informado | H4: Razón social | I4: Dirección | J4: Código dpto. | K4: Código mcp | L4: Código País | M4: Correo electrónico | N4: Valor total del ingreso | O4: Valor del ingreso no constitutivo de renta ni ganancia ocasional solicitado

Sheet 2280
A1: 2280 | B1: Deducción empleadas victimas de la violencia V1
A3: Tipo de documento empleada | B3: Número identificación empleada | C3: Primer apellido | D3: Segundo apellido | E3: Primer nombre | F3: Otros nombres | G3: Fecha inicio contrato | H3: Fecha final contrato | I3: Tipo medida certificación | J3: Cargo contratado | K3: Salario pagados durante el periodo | L3: Prestaciones sociales pagados durante el periodo | M3: Edad mujer contratada | N3: Nivel educativo

Sheet 1036
A1: 1036 | B1: Información de subordinadas o vinculadas del exterior V8
I2: 169 Colombia
A3: Tipo de informante | B3: Identificación de la subordinada o vinculada | C3: Razón social de la subordinada o vinculada | D3: País de la subordinada o vinculada | E3: Vehiculo de inversión | F3: Forma de control | G3: Tipo de control | H3: Participación en el capital de la subordinada o vinculada | I3: Participación en los resultados de la subordinada o vinculada

Sheet 1035
A1: 1035 | B1: Entidades subordinadas o controladas nacionales V7
A3: Tipo de documento | B3: Identificación de la subordinada | C3: Primer apellido del informado | D3: Segundo apellido del informado | E3: Primer nombre del informado | F3: Otros nombres del informado | G3: Razón social de la subordinada | H3: Dirección | I3: Código dpto. | J3: Código mcp | K3: Vehiculo de inversión | L3: Forma de control | M3: Tipo de control | N3: Participación en el capital de la subordinada o vinculada | O3: Participación en los resultados de la subordinada o vinculada

Sheet 1034
A3: 1034 | B3: Información de estados financieros consolidados- Grupos economicos V6
A4: Las entidades que en aplicación de las normas de contabilidad e información financiera vigentes en Colombia se encuentren en la obligación de preparar y difundir estados inancieros consolidados.
A7: Concepto | B7: Valor contable al -31-12

Sheet 5253
A1: 5253 | B1: Información de beneficiarios efectivos V1
A2: Las sociedades colombianas que sean subsidiarias o filiales de sociedades nacionales o del exterior, establecimientos permanentes de empresas del exterior, | J2: 169 Colombia
A3: Tipo de informante | B3: Tipo de documento | C3: Número identificación | D3: Primer apellido del informado | E3: Segundo apellido del informado | F3: Primer nombre del informado | G3: Otros nombres del informado | H3: Fecha de nacimiento | I3: País de nacionalidad | J3: País de residencia o domicilio | K3: Fecha final como beneficiario efectivo

Sheet 2575
A1: 2575 | B1: Donaciones recibidas y certificadas por entidades no contribuyentes V1
A3: Forma de donación | B3: Monto de la donación | C3: Tipo de persona donante | D3: Tipo de documento | E3: Número identificación | F3: Primer apellido del informado | G3: Segundo apellido del informado | H3: Primer nombre del informado | I3: Otros nombres del informado | J3: Razón social

Sheet Control
A2: Envio | B2: Formato | C2: Version | D2: Registros
A3: 1
A4: 2
A5: 3
A6: 4
A7: 5
A8: 6
A9: 7
A10: 8
A11: 9
A12: 10
A13: 11
A14: 12
A15: 13

Sheet Info
B3: PAISES | E3: DEPARTAMENTOS | H3: TIPO DE DOCUMENTOS
B4: 013 | C4: AFGANISTAN | E4: 91 | F4: Amazonas | H4: 11 | I4: Registro civil de nacimiento
B5: 017 | C5: ALBANIA | E5: 05 | F5: Antioquia | H5: 12 | I5: Tarjeta de identidad
B6: 023 | C6: ALEMANIA | E6: 81 | F6: Arauca | H6: 13 | I6: Cédula de ciudadanía
B7: 037 | C7: ANDORRA | E7: 08 | F7: Atlántico | H7: 21 | I7: Tarjeta de extranjería
B8: 040 | C8: ANGOLA | E8: 11 | F8: Bogotá D.C. | H8: 22 | I8: Cédula de extranjería
B9: 041 | C9: ANGUILLA | E9: 13 | F9: Bolívar | H9: 31 | I9: Nit
B10: 043 | C10: ANTIGUA Y BARBUDA | E10: 15 | F10: Boyacá | H10: 41 | I10: Pasaporte
B11: 047 | C11: ANTILLAS HOLANDESAS | E11: 17 | F11: Caldas | H11: 42 | I11: Tipo de documento Extranjero
B12: 053 | C12: ARABIA SAUDITA | E12: 18 | F12: Caquetá | H12: 43 | I12: Sin identificación del exterior o para uso definido por la DIAN
B13: 059 | C13: ARGELIA | E13: 85 | F13: Casanare
B14: 063 | C14: ARGENTINA | E14: 19 | F14: Cauca
B15: 026 | C15: ARMENIA | E15: 20 | F15: Cesar
B16: 027 | C16: ARUBA | E16: 27 | F16: Chocó
B17: 069 | C17: AUSTRALIA | E17: 23 | F17: Córdoba
B18: 072 | C18: AUSTRIA | E18: 25 | F18: Cundinamarca
B19: 074 | C19: AZERBAIJAN | E19: 94 | F19: Guainía
B20: 077 | C20: BAHAMAS | E20: 95 | F20: Guaviare
B21: 080 | C21: BAHREIN | E21: 41 | F21: Huila
B22: 081 | C22: BANGLADESH | E22: 4+E224 | F22: La Guajira
B23: 083 | C23: BARBADOS | E23: 47 | F23: Magdalena
B24: 087 | C24: BELGICA | E24: 50 | F24: Meta
... B26: 091 | C26: BELORUS | E26: 54 | F26: Norte de Santander
B27: 229 | C27: BENIN | E27: 86 | F27: Putumayo
B28: 090 | C28: BERMUDAS | E28: 63 | F28: Quindío
B29: 093 | C29: BIRMANIA (MYANMAR) | E29: 66 | F29: Risaralda
B30: 097 | C30: BOLIVIA | E30: 88 | F30: San Andrés
B31: 029 | C31: BOSNIA-HERZEGOVINA | E31: 68 | F31: Santander
B32: 101 | C32: BOTSWANA | E32: 70 | F32: Sucre
B33: 105 | C33: BRASIL | E33: 73 | F33: Tolima
B34: 108 | C34: BRUNEI DARUSSALAM | E34: 76 | F34: Valle del Cauca
B35: 111 | C35: BULGARIA | E35: 97 | F35: Vaupés
B36: 031 | C36: BURKINA FASSO | E36: 99 | F36: Vichada
B37: 115 | C37: BURUNDI
B38: 119 | C38: BUTAN
B39: 127 | C39: CABO VERDE
B40: 137 | C40: CAIMAN, ISLAS
B41: 145 | C41: CAMERUN, REPUBLICA U
B42: 149 | C42: CANADA
B43: 155 | C43: CANAL(NORMANDAS),ISL
...

Sheet clientes
A1: nit | B1: direccion | C1: dpto | D1: ciudad | E1: dpto | F1: munic | G1: tipo_doc | H1: razon | I1: nombre1 | J1: NOMBRE2 | K1: apellido1 | L1: apellido2
A2: 900276962 | B2: Cra. 52 # 70 - 168 | C2: Atlántico | D2: Barranquilla | E2: 08 | F2: 001 | G2: 31 | H2: D1 S A S
A3: 901873198 | B3: Cl. 116 #42b 91 | C3: Atlántico | D3: Puerto Colombia | E3: 08 | F3: 573 | G3: 31 | H3: FERRETERIA PONQUIFON SEDE 93
A4: 32826857 | B4: Cra. 51B #106-200 | C4: Atlántico | D4: Barranquilla | E4: 08 | F4: 001 | G4: 13 | I4: MARENA | K4: DE LA ROSA | L4: NIEBLES
A5: 800051755 | B5: Calle 66 Vía 40, Esquina | C5: Atlántico | D5: Barranquilla | E5: 08 | F5: 001 | G5: 31 | H5: NULE MARINO & COMPAÑIA SAS
A6: 800165377 | B6: Carrera 51B #93-119 | C6: Atlántico | D6: Barranquilla | E6: 08 | F6: 001 | G6: 31 | H6: GRUPO DECOR S.A.S.
A7: 800165720 | B7: Carrera 41 No. 46 - 137 | C7: Atlántico | D7: Barranquilla | E7: 08 | F7: 001 | G7: 31 | H7: ALCANTARA ASOCIADOS S.A.S.
A8: 800165815 | B8: Cra. 56 #5c - 50, | C8: Cundinamarca | D8: Bogotá | E8: 11 | F8: 001 | G8: 31 | H8: TEXTILES 1 x 1 SAS
A9: 800242106 | B9: Cra. 53 #98-2 | C9: Atlántico | D9: Barranquilla | E9: 08 | F9: 001 | G9: 31 | H9: SODIMAC COLOMBIA S.A.
A10: 802002267 | B10: CALLE 77 B CR 59 61 OF1002 | C10: Atlántico | D10: Barranquilla | E10: 08 | F10: 001 | G10: 31 | H10: TEXVIGAR S.A.S.
A11: 802003599 | B11: Cl. 44 #43-115 | C11: Atlántico | D11: Barranquilla | E11: 08 | F11: 001 | G11: 31 | H11: DISNAR S.A.S - VILLA CAMPESTRE
A12: 802004266 | B12: Carrera 43 #80-120. | C12: Atlántico | D12: Barranquilla | E12: 08 | F12: 001 | G12: 31 | H12: FERRETERIA METROPOLIS S.A.S.
A13: 802006391 | B13: Cra. 51 #76 - 47 | C13: Atlántico | D13: Barranquilla | E13: 08 | F13: 001 | G13: 31 | H13: CREPES CARIBE S.A.
A14: 802017066 | B14: Carrera 38 No. 69D - 29 | C14: Atlántico | D14: Barranquilla | E14: 08 | F14: 001 | G14: 31 | H14: SODICSA S.A.S
A15: 802023507 | B15: Carrera 43 # 9-97, Local 42, 43, 44 y 45 | C15: Atlántico | D15: Barranquilla | E15: 08 | F15: 001 | G15: 31 | H15: CONNY DE LA COSTA S.A.S.
A16: 811009788 | B16: Cl. 84b #38 - 11 | C16: Atlántico | D16: Barranquilla | E16: 08 | F16: 001 | G16: 31 | H16: DISTRACOM S.A.
... A25: 860503159 | B25: Carrera 53 No. 94-50, Local 3 | C25: Atlántico | D25: Barranquilla | E25: 08 | F25: 001 | G25: 31 | H25: PASH S.A.S
A26: 8674041 | B26: Calle 54 No. 42-15 | C26: Atlántico | D26: Barranquilla | E26: 08 | F26: 001 | G26: 13 | I26: ENRIQUE | J26: RICARDO | K26: HENRIQUEZ | L26: ARAZO
A27: 890102010 | B27: Cra. 53 #106 - 280 | C27: Atlántico | D27: Barranquilla | E27: 08 | F27: 001 | G27: 31 | H27: CAMARA DE COMERCIO DE BARRANQUILLA
A28: 890102603 | B28: Cra. 38 #36-02 | C28: Atlántico | D28: Barranquilla | E28: 08 | F28: 001 | G28: 31 | H28: GRUPO MI CORRAL S.A
A29: 890115118 | B29: Cra. 38 #36-02 | C29: Atlántico | D29: Barranquilla | E29: 08 | F29: 001 | G29: 31 | H29: FRENOS BARRANQUILLA SAS
A30: 890115294 | B30: Cra. 55 #99 51 | C30: Atlántico | D30: Barranquilla | E30: 08 | F30: 001 | G30: 31 | H30: HOT AMERICA`S FAVORITE PIZZA S.A.S
A31: 890900943 | B31: Calle 98 # 51B - 91 | C31: Atlántico | D31: Barranquilla | E31: 08 | F31: 001 | G31: 31 | H31: COLOMBIANA DE COMERCIO S.A.
A32: 900021337 | B32: Calle 40 No. 44-39, Oficina 6H | C32: Atlántico | D32: Barranquilla | E32: 08 | F32: 001 | G32: 31 | H32: CREDISEGUROS DE LA COSTA LTDA
A33: 900059238 | B33: Cra. 51B #106-200 | C33: Atlántico | D33: Barranquilla | E33: 08 | F33: 001 | G33: 31 | H33: MAKRO SUPERMAYORISTA S.A.S
A34: 900214193 | B34: CALLE 110 43 C 735 | C34: Atlántico | D34: Barranquilla | E34: 08 | F34: 001 | G34: 31 | H34: INVERSIONES COMBGAS S.A.S
A35: 900230625 | B35: Carrera 43 # 82-09 | C35: Atlántico | D35: Barranquilla | E35: 08 | F35: 001 | G35: 31 | H35: ESTACION DE SERVICIO COLISEO S.A
A36: 900276962 | B36: Cra. 52 # 70 - 168 | C36: Atlántico | D36: Barranquilla | E36: 08 | F36: 001 | G36: 31 | H36: D1 S A S
A37: 900309367 | B37: CALLE 1 #10-50 LTE | C37: Atlántico | D37: Barranquilla | E37: 08 | F37: 001 | G37: 31 | H37: SANTA MARIA DEL MAR S.A.S
A38: 900319753 | B38: Carrera 53 con calle 106 esquina | C38: Atlántico | D38: Barranquilla | E38: 08 | F38: 001 | G38: 31 | H38: PRICESMART COLOMBIA S.A.S.
... A121: 800098601 | B121: Via 40 60 180 Sec La Loma 3 | C121: Atlántico | D121: BARRANQUILLA | E121: 08 | F121: 001 | G121: 31 | H121: UNIFEL S.A.
A122: 79148397 | B122: CL 10 20 35 OF 295 | C122: BOGOTÁ D.C | D122: Bogotá | E122: 11 | F122: 001 | G122: 13 | I122: JUAN | J122: CARLOS | K122: MOJOCOA | L122: PARADA
A123: 10934103 | B123: CL 36 1 91 BRR CENTRO | C123: Córdoba | D123: Montería | E123: 23 | F123: 001 | G123: 13 | I123: LUIS | J123: CARLOS | K123: CORREA | L123: CASTRO
A124: 43785419 | B124: CL 465 54 24 | C124: Antioquia | D124: Medellín | E124: 05 | F124: 001 | G124: 13 | I124: MARIA | J124: FLORELBA | K124: GALLEGO | L124: GOMEZ
A125: 70696078 | B125: CL 465 54 24 | C125: Antioquia | D125: Medellín | E125: 05 | F125: 001 | G125: 13 | I125: WILLIAM | J125: DARIO | K125: GALLEGO | L125: GOMEZ
A126: 70353742 | B126: CL 8 14 15 | C126: Córdoba | D126: CIENAGA DE ORO | E126: 23 | F126: 189 | G126: 13 | I126: JOHNY | J126: ANDRES | K126: GIRALDO | L126: MARIN
A127: 1124060096 | B127: CR 52 A 45 33 | C127: Antioquia | D127: Medellín | E127: 05 | F127: 001 | G127: 13 | I127: RABIH | K127: SERHAN | L127: TOUFIC
A128: 9868376 | B128: CL 36 2 42 P 1 Lc 1 | C128: Cordoba | D128: Monteria | E128: 23 | F128: 001 | G128: 13 | I128: FRANK | J128: FERNANDO | K128: ZULUAGA | L128: SANCHEZ
A129: 13745511 | B129: CL 4 6 33 CRR LA LOMA | C129: Cesar | D129: El Paso | E129: 20 | F129: 250 | G129: 13 | I129: RUFINO | K129: PARDO | L129: MILLAN
A130: 70725876 | B130: Cra 2 36 35 | C130: Cordoba | D130: Monteria | E130: 23 | F130: 001 | G130: 13 | I130: EFREN | J130: DE JESUS | K130: LOPEZ | L130: VALENCIA
...
